2024-09-01 00:13:16,009 - web_UI - ERROR - Traceback (most recent call last):
  File "C:\Users\16946\Desktop\pythonProject\Auto_wed_current\Auto_UI\GUI_ComboBox\web_combobox.py", line 180, in <lambda>
    control_groove_locals[i + 'test'] =  lambda : self.ws.option_value(control_locals_template, control_locals_file, control_locals_sheet, control_locals_wait, control_locals_QlineEdit, self)
                                                  ^^^^^^^^^^^^^^^^^^^^^^^^^^^^^^^^^^^^^^^^^^^^^^^^^^^^^^^^^^^^^^^^^^^^^^^^^^^^^^^^^^^^^^^^^^^^^^^^^^^^^^^^^^^^^^^^^^^^^^^^^^^^^^^^^^^^^^^^^^^^^
  File "C:\Users\16946\Desktop\pythonProject\Auto_wed_current\Auto_UI\GUI_ComboBox\web_combobox_sheet.py", line 49, in option_value
    self.combocheckbox(sheets, comboBox_template, comboBox_file, comboBox_sheet, comboBox_wait, control_locals_QlineEdit, web_combobox) # 执行一下函数
    ^^^^^^^^^^^^^^^^^^^^^^^^^^^^^^^^^^^^^^^^^^^^^^^^^^^^^^^^^^^^^^^^^^^^^^^^^^^^^^^^^^^^^^^^^^^^^^^^^^^^^^^^^^^^^^^^^^^^^^^^^^^^^^^^^^^
  File "C:\Users\16946\Desktop\pythonProject\Auto_wed_current\Auto_UI\GUI_ComboBox\web_combobox_sheet.py", line 85, in combocheckbox
    for i in range(len(control_locals_QlineEdit.items)):
             ^^^^^
  File "_pydevd_bundle\\pydevd_cython_win32_311_64.pyx", line 1187, in _pydevd_bundle.pydevd_cython_win32_311_64.SafeCallWrapper.__call__
  File "_pydevd_bundle\\pydevd_cython_win32_311_64.pyx", line 627, in _pydevd_bundle.pydevd_cython_win32_311_64.PyDBFrame.trace_dispatch
  File "_pydevd_bundle\\pydevd_cython_win32_311_64.pyx", line 1103, in _pydevd_bundle.pydevd_cython_win32_311_64.PyDBFrame.trace_dispatch
  File "_pydevd_bundle\\pydevd_cython_win32_311_64.pyx", line 1065, in _pydevd_bundle.pydevd_cython_win32_311_64.PyDBFrame.trace_dispatch
  File "_pydevd_bundle\\pydevd_cython_win32_311_64.pyx", line 585, in _pydevd_bundle.pydevd_cython_win32_311_64.PyDBFrame.do_wait_suspend
  File "C:\Program Files\JetBrains\PyCharm 2024.2.0.1\plugins\python-ce\helpers\pydev\pydevd.py", line 1207, in do_wait_suspend
    self._do_wait_suspend(thread, frame, event, arg, suspend_type, from_this_thread)
  File "C:\Program Files\JetBrains\PyCharm 2024.2.0.1\plugins\python-ce\helpers\pydev\pydevd.py", line 1222, in _do_wait_suspend
    time.sleep(0.01)
KeyboardInterrupt

2024-09-01 00:34:14,134 - web_UI - ERROR - Traceback (most recent call last):
  File "C:\Users\16946\Desktop\pythonProject\Auto_wed_current\Auto_UI\GUI_Perform\web_perform_func.py", line 71, in perform_start
    perform_result, csv_file = self.cw.csv_data_write()
                               ^^^^^^^^^^^^^^^^^^^^^^^^
  File "C:\Users\16946\Desktop\pythonProject\Auto_wed_current\Auto_UI\GUI_CSV\web_csv_write.py", line 35, in csv_data_write
    csv_file = []
               ^^
  File "_pydevd_bundle\\pydevd_cython_win32_311_64.pyx", line 1187, in _pydevd_bundle.pydevd_cython_win32_311_64.SafeCallWrapper.__call__
  File "_pydevd_bundle\\pydevd_cython_win32_311_64.pyx", line 627, in _pydevd_bundle.pydevd_cython_win32_311_64.PyDBFrame.trace_dispatch
  File "_pydevd_bundle\\pydevd_cython_win32_311_64.pyx", line 1103, in _pydevd_bundle.pydevd_cython_win32_311_64.PyDBFrame.trace_dispatch
  File "_pydevd_bundle\\pydevd_cython_win32_311_64.pyx", line 1065, in _pydevd_bundle.pydevd_cython_win32_311_64.PyDBFrame.trace_dispatch
  File "_pydevd_bundle\\pydevd_cython_win32_311_64.pyx", line 585, in _pydevd_bundle.pydevd_cython_win32_311_64.PyDBFrame.do_wait_suspend
  File "C:\Program Files\JetBrains\PyCharm 2024.2.0.1\plugins\python-ce\helpers\pydev\pydevd.py", line 1207, in do_wait_suspend
    self._do_wait_suspend(thread, frame, event, arg, suspend_type, from_this_thread)
  File "C:\Program Files\JetBrains\PyCharm 2024.2.0.1\plugins\python-ce\helpers\pydev\pydevd.py", line 1222, in _do_wait_suspend
    time.sleep(0.01)
KeyboardInterrupt

2024-09-01 00:35:28,568 - web_UI - ERROR - Traceback (most recent call last):
  File "C:\Users\16946\Desktop\pythonProject\Auto_wed_current\Auto_UI\GUI_Perform\web_perform_func.py", line 71, in perform_start
    perform_result, csv_file = self.cw.csv_data_write()
                               ^^^^^^^^^^^^^^^^^^^^^^^^
  File "C:\Users\16946\Desktop\pythonProject\Auto_wed_current\Auto_UI\GUI_CSV\web_csv_write.py", line 38, in csv_data_write
    csv_file.append(j[0])
    ^^^^^^^^
  File "_pydevd_bundle\\pydevd_cython_win32_311_64.pyx", line 1187, in _pydevd_bundle.pydevd_cython_win32_311_64.SafeCallWrapper.__call__
  File "_pydevd_bundle\\pydevd_cython_win32_311_64.pyx", line 627, in _pydevd_bundle.pydevd_cython_win32_311_64.PyDBFrame.trace_dispatch
  File "_pydevd_bundle\\pydevd_cython_win32_311_64.pyx", line 1103, in _pydevd_bundle.pydevd_cython_win32_311_64.PyDBFrame.trace_dispatch
  File "_pydevd_bundle\\pydevd_cython_win32_311_64.pyx", line 1065, in _pydevd_bundle.pydevd_cython_win32_311_64.PyDBFrame.trace_dispatch
  File "_pydevd_bundle\\pydevd_cython_win32_311_64.pyx", line 585, in _pydevd_bundle.pydevd_cython_win32_311_64.PyDBFrame.do_wait_suspend
  File "C:\Program Files\JetBrains\PyCharm 2024.2.0.1\plugins\python-ce\helpers\pydev\pydevd.py", line 1207, in do_wait_suspend
    self._do_wait_suspend(thread, frame, event, arg, suspend_type, from_this_thread)
  File "C:\Program Files\JetBrains\PyCharm 2024.2.0.1\plugins\python-ce\helpers\pydev\pydevd.py", line 1222, in _do_wait_suspend
    time.sleep(0.01)
KeyboardInterrupt

2024-09-01 00:36:36,789 - web_UI - ERROR - Traceback (most recent call last):
  File "C:\Users\16946\Desktop\pythonProject\Auto_wed_current\Auto_UI\GUI_Perform\web_perform_func.py", line 71, in perform_start
    perform_result, csv_file = self.cw.csv_data_write()
                               ^^^^^^^^^^^^^^^^^^^^^^^^
  File "C:\Users\16946\Desktop\pythonProject\Auto_wed_current\Auto_UI\GUI_CSV\web_csv_write.py", line 40, in csv_data_write
    for list in self.combobox_list:
                ^^^^
  File "_pydevd_bundle\\pydevd_cython_win32_311_64.pyx", line 1187, in _pydevd_bundle.pydevd_cython_win32_311_64.SafeCallWrapper.__call__
  File "_pydevd_bundle\\pydevd_cython_win32_311_64.pyx", line 627, in _pydevd_bundle.pydevd_cython_win32_311_64.PyDBFrame.trace_dispatch
  File "_pydevd_bundle\\pydevd_cython_win32_311_64.pyx", line 1103, in _pydevd_bundle.pydevd_cython_win32_311_64.PyDBFrame.trace_dispatch
  File "_pydevd_bundle\\pydevd_cython_win32_311_64.pyx", line 1065, in _pydevd_bundle.pydevd_cython_win32_311_64.PyDBFrame.trace_dispatch
  File "_pydevd_bundle\\pydevd_cython_win32_311_64.pyx", line 585, in _pydevd_bundle.pydevd_cython_win32_311_64.PyDBFrame.do_wait_suspend
  File "C:\Program Files\JetBrains\PyCharm 2024.2.0.1\plugins\python-ce\helpers\pydev\pydevd.py", line 1207, in do_wait_suspend
    self._do_wait_suspend(thread, frame, event, arg, suspend_type, from_this_thread)
  File "C:\Program Files\JetBrains\PyCharm 2024.2.0.1\plugins\python-ce\helpers\pydev\pydevd.py", line 1222, in _do_wait_suspend
    time.sleep(0.01)
KeyboardInterrupt

2024-09-01 11:08:37,987 - web_UI - ERROR - Traceback (most recent call last):
  File "C:\Users\16946\Desktop\pythonProject\Auto_wed_current\Auto_UI\GUI_Perform\web_perform_func.py", line 71, in perform_start
    perform_result, csv_file = self.cw.csv_data_write()
                               ^^^^^^^^^^^^^^^^^^^^^^^^
  File "C:\Users\16946\Desktop\pythonProject\Auto_wed_current\Auto_UI\GUI_CSV\web_csv_write.py", line 38, in csv_data_write
    if self.combobox_list[i][j] != '':
       ^^^^
  File "_pydevd_bundle\\pydevd_cython_win32_311_64.pyx", line 1187, in _pydevd_bundle.pydevd_cython_win32_311_64.SafeCallWrapper.__call__
  File "_pydevd_bundle\\pydevd_cython_win32_311_64.pyx", line 627, in _pydevd_bundle.pydevd_cython_win32_311_64.PyDBFrame.trace_dispatch
  File "_pydevd_bundle\\pydevd_cython_win32_311_64.pyx", line 1103, in _pydevd_bundle.pydevd_cython_win32_311_64.PyDBFrame.trace_dispatch
  File "_pydevd_bundle\\pydevd_cython_win32_311_64.pyx", line 1065, in _pydevd_bundle.pydevd_cython_win32_311_64.PyDBFrame.trace_dispatch
  File "_pydevd_bundle\\pydevd_cython_win32_311_64.pyx", line 585, in _pydevd_bundle.pydevd_cython_win32_311_64.PyDBFrame.do_wait_suspend
  File "C:\Program Files\JetBrains\PyCharm 2024.2.0.1\plugins\python-ce\helpers\pydev\pydevd.py", line 1207, in do_wait_suspend
    self._do_wait_suspend(thread, frame, event, arg, suspend_type, from_this_thread)
  File "C:\Program Files\JetBrains\PyCharm 2024.2.0.1\plugins\python-ce\helpers\pydev\pydevd.py", line 1222, in _do_wait_suspend
    time.sleep(0.01)
KeyboardInterrupt

2024-09-01 11:19:19,968 - web_UI - ERROR - Traceback (most recent call last):
  File "C:\Users\16946\Desktop\pythonProject\Auto_wed_current\Auto_UI\GUI_Perform\web_perform_func.py", line 71, in perform_start
    perform_result, csv_file = self.cw.csv_data_write()
                               ^^^^^^^^^^^^^^^^^^^^^^^^
  File "C:\Users\16946\Desktop\pythonProject\Auto_wed_current\Auto_UI\GUI_CSV\web_csv_write.py", line 40, in csv_data_write
    for j in self.combobox_list[i]:
             ^^^^
  File "_pydevd_bundle\\pydevd_cython_win32_311_64.pyx", line 1187, in _pydevd_bundle.pydevd_cython_win32_311_64.SafeCallWrapper.__call__
  File "_pydevd_bundle\\pydevd_cython_win32_311_64.pyx", line 627, in _pydevd_bundle.pydevd_cython_win32_311_64.PyDBFrame.trace_dispatch
  File "_pydevd_bundle\\pydevd_cython_win32_311_64.pyx", line 1103, in _pydevd_bundle.pydevd_cython_win32_311_64.PyDBFrame.trace_dispatch
  File "_pydevd_bundle\\pydevd_cython_win32_311_64.pyx", line 1065, in _pydevd_bundle.pydevd_cython_win32_311_64.PyDBFrame.trace_dispatch
  File "_pydevd_bundle\\pydevd_cython_win32_311_64.pyx", line 585, in _pydevd_bundle.pydevd_cython_win32_311_64.PyDBFrame.do_wait_suspend
  File "C:\Program Files\JetBrains\PyCharm 2024.2.0.1\plugins\python-ce\helpers\pydev\pydevd.py", line 1207, in do_wait_suspend
    self._do_wait_suspend(thread, frame, event, arg, suspend_type, from_this_thread)
  File "C:\Program Files\JetBrains\PyCharm 2024.2.0.1\plugins\python-ce\helpers\pydev\pydevd.py", line 1222, in _do_wait_suspend
    time.sleep(0.01)
KeyboardInterrupt

2024-09-01 11:24:46,766 - web_UI - ERROR - Traceback (most recent call last):
  File "C:\Users\16946\Desktop\pythonProject\Auto_wed_current\Auto_UI\GUI_Perform\web_perform_func.py", line 71, in perform_start
    perform_result, csv_file = self.cw.csv_data_write()
                               ^^^^^^^^^^^^^^^^^^^^^^^^
  File "C:\Users\16946\Desktop\pythonProject\Auto_wed_current\Auto_UI\GUI_CSV\web_csv_write.py", line 42, in csv_data_write
    for i in self.combobox_list:
             ^^^^
  File "_pydevd_bundle\\pydevd_cython_win32_311_64.pyx", line 1187, in _pydevd_bundle.pydevd_cython_win32_311_64.SafeCallWrapper.__call__
  File "_pydevd_bundle\\pydevd_cython_win32_311_64.pyx", line 627, in _pydevd_bundle.pydevd_cython_win32_311_64.PyDBFrame.trace_dispatch
  File "_pydevd_bundle\\pydevd_cython_win32_311_64.pyx", line 1103, in _pydevd_bundle.pydevd_cython_win32_311_64.PyDBFrame.trace_dispatch
  File "_pydevd_bundle\\pydevd_cython_win32_311_64.pyx", line 1065, in _pydevd_bundle.pydevd_cython_win32_311_64.PyDBFrame.trace_dispatch
  File "_pydevd_bundle\\pydevd_cython_win32_311_64.pyx", line 585, in _pydevd_bundle.pydevd_cython_win32_311_64.PyDBFrame.do_wait_suspend
  File "C:\Program Files\JetBrains\PyCharm 2024.2.0.1\plugins\python-ce\helpers\pydev\pydevd.py", line 1207, in do_wait_suspend
    self._do_wait_suspend(thread, frame, event, arg, suspend_type, from_this_thread)
  File "C:\Program Files\JetBrains\PyCharm 2024.2.0.1\plugins\python-ce\helpers\pydev\pydevd.py", line 1222, in _do_wait_suspend
    time.sleep(0.01)
KeyboardInterrupt

2024-09-01 11:25:05,908 - web_UI - ERROR - Traceback (most recent call last):
  File "C:\Users\16946\Desktop\pythonProject\Auto_wed_current\Auto_UI\GUI_Perform\web_perform_func.py", line 71, in perform_start
    perform_result, csv_file = self.cw.csv_data_write()
    ^^^^^^^^^^^^^^^^^^^^^^^^
TypeError: cannot unpack non-iterable NoneType object

2024-09-01 23:11:30,966 - web_UI - ERROR - Traceback (most recent call last):
  File "C:\Users\16946\Desktop\pythonProject\Auto_wed_current\Auto_execute\execute_while.py", line 47, in execute_function_original
    excel = excel_all(row, self.excel_file, excel_sheet, self.data_judge)
            ^^^^^^^^^^^^^^^^^^^^^^^^^^^^^^^^^^^^^^^^^^^^^^^^^^^^^^^^^^^^^
  File "C:\Users\16946\Desktop\pythonProject\Auto_wed_current\Auto_data\excel.py", line 27, in __init__
    self.file_original = filename().filename(r'\Auto_file\原始导入excel模板\{}'.format(excel_file)) # 原始数据
                         ^^^^^^^^^^^^^^^^^^^
AttributeError: 'filename' object has no attribute 'filename'

2024-09-01 23:11:44,215 - web_UI - ERROR - Traceback (most recent call last):
  File "C:\Users\16946\Desktop\pythonProject\Auto_wed_current\Auto_execute\execute_while.py", line 47, in execute_function_original
    excel = excel_all(row, self.excel_file, excel_sheet, self.data_judge)
            ^^^^^^^^^^^^^^^^^^^^^^^^^^^^^^^^^^^^^^^^^^^^^^^^^^^^^^^^^^^^^
  File "C:\Users\16946\Desktop\pythonProject\Auto_wed_current\Auto_data\excel.py", line 27, in __init__
    self.file_original = filename().filename(r'\Auto_file\原始导入excel模板\{}'.format(excel_file)) # 原始数据
                         ^^^^^^^^^^^^^^^^^^^
AttributeError: 'filename' object has no attribute 'filename'

2024-09-01 23:11:44,216 - web_UI - ERROR - Traceback (most recent call last):
  File "C:\Users\16946\Desktop\pythonProject\Auto_wed_current\Auto_execute\execute_while.py", line 47, in execute_function_original
    excel = excel_all(row, self.excel_file, excel_sheet, self.data_judge)
            ^^^^^^^^^^^^^^^^^^^^^^^^^^^^^^^^^^^^^^^^^^^^^^^^^^^^^^^^^^^^^
  File "C:\Users\16946\Desktop\pythonProject\Auto_wed_current\Auto_data\excel.py", line 27, in __init__
    self.file_original = filename().filename(r'\Auto_file\原始导入excel模板\{}'.format(excel_file)) # 原始数据
                         ^^^^^^^^^^^^^^^^^^^
AttributeError: 'filename' object has no attribute 'filename'

2024-09-01 23:11:44,217 - web_UI - ERROR - Traceback (most recent call last):
  File "C:\Users\16946\Desktop\pythonProject\Auto_wed_current\Auto_execute\execute_while.py", line 47, in execute_function_original
    excel = excel_all(row, self.excel_file, excel_sheet, self.data_judge)
            ^^^^^^^^^^^^^^^^^^^^^^^^^^^^^^^^^^^^^^^^^^^^^^^^^^^^^^^^^^^^^
  File "C:\Users\16946\Desktop\pythonProject\Auto_wed_current\Auto_data\excel.py", line 27, in __init__
    self.file_original = filename().filename(r'\Auto_file\原始导入excel模板\{}'.format(excel_file)) # 原始数据
                         ^^^^^^^^^^^^^^^^^^^
AttributeError: 'filename' object has no attribute 'filename'

2024-09-01 23:11:44,218 - web_UI - ERROR - Traceback (most recent call last):
  File "C:\Users\16946\Desktop\pythonProject\Auto_wed_current\Auto_execute\execute_while.py", line 47, in execute_function_original
    excel = excel_all(row, self.excel_file, excel_sheet, self.data_judge)
            ^^^^^^^^^^^^^^^^^^^^^^^^^^^^^^^^^^^^^^^^^^^^^^^^^^^^^^^^^^^^^
  File "C:\Users\16946\Desktop\pythonProject\Auto_wed_current\Auto_data\excel.py", line 27, in __init__
    self.file_original = filename().filename(r'\Auto_file\原始导入excel模板\{}'.format(excel_file)) # 原始数据
                         ^^^^^^^^^^^^^^^^^^^
AttributeError: 'filename' object has no attribute 'filename'

2024-09-01 23:11:44,219 - web_UI - ERROR - Traceback (most recent call last):
  File "C:\Users\16946\Desktop\pythonProject\Auto_wed_current\Auto_execute\execute_while.py", line 47, in execute_function_original
    excel = excel_all(row, self.excel_file, excel_sheet, self.data_judge)
            ^^^^^^^^^^^^^^^^^^^^^^^^^^^^^^^^^^^^^^^^^^^^^^^^^^^^^^^^^^^^^
  File "C:\Users\16946\Desktop\pythonProject\Auto_wed_current\Auto_data\excel.py", line 27, in __init__
    self.file_original = filename().filename(r'\Auto_file\原始导入excel模板\{}'.format(excel_file)) # 原始数据
                         ^^^^^^^^^^^^^^^^^^^
AttributeError: 'filename' object has no attribute 'filename'

2024-09-01 23:14:46,883 - web_UI - ERROR - Traceback (most recent call last):
  File "C:\Users\16946\Desktop\pythonProject\.venv\Lib\site-packages\xlrd\book.py", line 466, in sheet_by_name
    sheetx = self._sheet_names.index(sheet_name)
             ^^^^^^^^^^^^^^^^^^^^^^^^^^^^^^^^^^^
ValueError: '原始模板' is not in list

During handling of the above exception, another exception occurred:

Traceback (most recent call last):
  File "C:\Users\16946\Desktop\pythonProject\Auto_wed_current\Auto_data\excel.py", line 42, in book_judge
    data = book.sheet_by_name(self.file_work)
           ^^^^^^^^^^^^^^^^^^^^^^^^^^^^^^^^^^
  File "C:\Users\16946\Desktop\pythonProject\.venv\Lib\site-packages\xlrd\book.py", line 468, in sheet_by_name
    raise XLRDError('No sheet named <%r>' % sheet_name)
xlrd.biffh.XLRDError: No sheet named <'原始模板'>

During handling of the above exception, another exception occurred:

Traceback (most recent call last):
  File "C:\Users\16946\Desktop\pythonProject\Auto_wed_current\Auto_execute\execute_while.py", line 48, in execute_function_original
    account = excel.excel_account()  # 获取account值
              ^^^^^^^^^^^^^^^^^^^^^
  File "C:\Users\16946\Desktop\pythonProject\Auto_wed_current\Auto_data\excel.py", line 81, in excel_account
    excel_account_valus = self.book_read_judge(4, self.data_judge)
                          ^^^^^^^^^^^^^^^^^^^^^^^^^^^^^^^^^^^^^^^^
  File "C:\Users\16946\Desktop\pythonProject\Auto_wed_current\Auto_data\excel.py", line 44, in book_judge
    raise error_reminder('excel_sheet', sheet=self.file_work)
Auto_wed_current.Auto_base.error_reminder.error_reminder: <exception str() failed>

2024-09-01 23:26:05,436 - web_UI - ERROR - Traceback (most recent call last):
  File "C:\Users\16946\Desktop\pythonProject\Auto_wed_current\Auto_base\wait.py", line 24, in wait_element
    WebDriverWait(self.driver, self.wait_time).until(EC.presence_of_all_elements_located((By.XPATH, self.xpath)))
  File "C:\Users\16946\Desktop\pythonProject\.venv\Lib\site-packages\selenium\webdriver\support\wait.py", line 105, in until
    raise TimeoutException(message, screen, stacktrace)
selenium.common.exceptions.TimeoutException: Message: 


During handling of the above exception, another exception occurred:

Traceback (most recent call last):
  File "C:\Users\16946\Desktop\pythonProject\Auto_wed_current\Auto_execute\execute_while.py", line 104, in execute_function_original
    driver_wait(row, xpath, account, error, self.wait_time, excel_file=self.excel_file, excel_sheet=excel_sheet).wait_element()
  File "C:\Users\16946\Desktop\pythonProject\Auto_wed_current\Auto_base\wait.py", line 26, in wait_element
    raise error_reminder('wait_element')
Auto_wed_current.Auto_base.error_reminder.error_reminder: <exception str() failed>

During handling of the above exception, another exception occurred:

Traceback (most recent call last):
  File "C:\Users\16946\Desktop\pythonProject\Auto_wed_current\Auto_execute\execute_while.py", line 137, in execute_function_original
    error_warning.error_screenshot()
  File "C:\Users\16946\Desktop\pythonProject\Auto_wed_current\Auto_base\error.py", line 26, in error_screenshot
    judge = setting_csv()
            ^^^^^^^^^^^^^
  File "C:\Users\16946\Desktop\pythonProject\Auto_wed_current\Auto_file\setting_csv.py", line 8, in setting_csv
    path = filename().filename(r'\Auto_file\配置文件\test_setting.csv')
           ^^^^^^^^^^^^^^^^^^^
AttributeError: 'filename' object has no attribute 'filename'

2024-09-01 23:26:49,805 - web_UI - ERROR - Traceback (most recent call last):
  File "C:\Users\16946\Desktop\pythonProject\Auto_wed_current\Auto_base\wait.py", line 24, in wait_element
    WebDriverWait(self.driver, self.wait_time).until(EC.presence_of_all_elements_located((By.XPATH, self.xpath)))
  File "C:\Users\16946\Desktop\pythonProject\.venv\Lib\site-packages\selenium\webdriver\support\wait.py", line 105, in until
    raise TimeoutException(message, screen, stacktrace)
selenium.common.exceptions.TimeoutException: Message: 


During handling of the above exception, another exception occurred:

Traceback (most recent call last):
  File "C:\Users\16946\Desktop\pythonProject\Auto_wed_current\Auto_execute\execute_while.py", line 104, in execute_function_original
    driver_wait(row, xpath, account, error, self.wait_time, excel_file=self.excel_file, excel_sheet=excel_sheet).wait_element()
  File "C:\Users\16946\Desktop\pythonProject\Auto_wed_current\Auto_base\wait.py", line 26, in wait_element
    raise error_reminder('wait_element')
Auto_wed_current.Auto_base.error_reminder.error_reminder: <exception str() failed>

During handling of the above exception, another exception occurred:

Traceback (most recent call last):
  File "C:\Users\16946\Desktop\pythonProject\Auto_wed_current\Auto_execute\execute_while.py", line 137, in execute_function_original
    error_warning.error_screenshot()
  File "C:\Users\16946\Desktop\pythonProject\Auto_wed_current\Auto_base\error.py", line 26, in error_screenshot
    judge = setting_csv()
            ^^^^^^^^^^^^^
  File "C:\Users\16946\Desktop\pythonProject\Auto_wed_current\Auto_file\setting_csv.py", line 8, in setting_csv
    path = filename().filename(r'\Auto_file\配置文件\test_setting.csv')
           ^^^^^^^^^^^^^^^^^^^
AttributeError: 'filename' object has no attribute 'filename'

2024-09-01 23:27:06,993 - web_UI - ERROR - Traceback (most recent call last):
  File "C:\Users\16946\Desktop\pythonProject\Auto_wed_current\Auto_base\wait.py", line 24, in wait_element
    WebDriverWait(self.driver, self.wait_time).until(EC.presence_of_all_elements_located((By.XPATH, self.xpath)))
  File "C:\Users\16946\Desktop\pythonProject\.venv\Lib\site-packages\selenium\webdriver\support\wait.py", line 105, in until
    raise TimeoutException(message, screen, stacktrace)
selenium.common.exceptions.TimeoutException: Message: 


During handling of the above exception, another exception occurred:

Traceback (most recent call last):
  File "C:\Users\16946\Desktop\pythonProject\Auto_wed_current\Auto_execute\execute_while.py", line 104, in execute_function_original
    driver_wait(row, xpath, account, error, self.wait_time, excel_file=self.excel_file, excel_sheet=excel_sheet).wait_element()
  File "C:\Users\16946\Desktop\pythonProject\Auto_wed_current\Auto_base\wait.py", line 26, in wait_element
    raise error_reminder('wait_element')
Auto_wed_current.Auto_base.error_reminder.error_reminder: <exception str() failed>

During handling of the above exception, another exception occurred:

Traceback (most recent call last):
  File "C:\Users\16946\Desktop\pythonProject\Auto_wed_current\Auto_execute\execute_while.py", line 137, in execute_function_original
    error_warning.error_screenshot()
  File "C:\Users\16946\Desktop\pythonProject\Auto_wed_current\Auto_base\error.py", line 26, in error_screenshot
    judge = setting_csv()
            ^^^^^^^^^^^^^
  File "C:\Users\16946\Desktop\pythonProject\Auto_wed_current\Auto_file\setting_csv.py", line 8, in setting_csv
    path = filename().filename(r'\Auto_file\配置文件\test_setting.csv')
           ^^^^^^^^^^^^^^^^^^^
AttributeError: 'filename' object has no attribute 'filename'

2024-09-01 23:31:22,410 - web_UI - ERROR - Traceback (most recent call last):
  File "C:\Users\16946\Desktop\pythonProject\Auto_wed_current\Auto_base\wait.py", line 24, in wait_element
    WebDriverWait(self.driver, self.wait_time).until(EC.presence_of_all_elements_located((By.XPATH, self.xpath)))
  File "C:\Users\16946\Desktop\pythonProject\.venv\Lib\site-packages\selenium\webdriver\support\wait.py", line 105, in until
    raise TimeoutException(message, screen, stacktrace)
selenium.common.exceptions.TimeoutException: Message: 


During handling of the above exception, another exception occurred:

Traceback (most recent call last):
  File "C:\Users\16946\Desktop\pythonProject\Auto_wed_current\Auto_execute\execute_while.py", line 104, in execute_function_original
    driver_wait(row, xpath, account, error, self.wait_time, excel_file=self.excel_file, excel_sheet=excel_sheet).wait_element()
  File "C:\Users\16946\Desktop\pythonProject\Auto_wed_current\Auto_base\wait.py", line 26, in wait_element
    raise error_reminder('wait_element')
Auto_wed_current.Auto_base.error_reminder.error_reminder: [上传模板V1.0.xls]>[调试1]>[第2行]报错，页面等待超时

During handling of the above exception, another exception occurred:

Traceback (most recent call last):
  File "C:\Users\16946\Desktop\pythonProject\Auto_wed_current\Auto_execute\execute_while.py", line 137, in execute_function_original
    error_warning.error_screenshot()
  File "C:\Users\16946\Desktop\pythonProject\Auto_wed_current\Auto_base\error.py", line 26, in error_screenshot
    judge = setting_csv()
            ^^^^^^^^^^^^^
  File "C:\Users\16946\Desktop\pythonProject\Auto_wed_current\Auto_file\setting_csv.py", line 8, in setting_csv
    path = filename().filename(r'\Auto_file\配置文件\test_setting.csv')
           ^^^^^^^^^^^^^^^^^^^
AttributeError: 'filename' object has no attribute 'filename'

2024-09-01 23:32:36,957 - web_UI - ERROR - Traceback (most recent call last):
  File "C:\Users\16946\Desktop\pythonProject\Auto_wed_current\Auto_UI\GUI_Perform\web_perform_func.py", line 122, in setting_window
    self.ps.setWindowModality(Qt.ApplicationModal)
                              ^^^^^^^^^^^^^^^^^^^
AttributeError: type object 'Qt' has no attribute 'ApplicationModal'

2024-09-01 23:34:06,257 - web_UI - ERROR - Traceback (most recent call last):
  File "C:\Users\16946\AppData\Local\Programs\Python\Python311\Lib\enum.py", line 688, in __call__
    def __call__(cls, value, names=None, *, module=None, qualname=None, type=None, start=1, boundary=None):
    
KeyboardInterrupt

2024-09-01 23:34:33,915 - web_UI - ERROR - Traceback (most recent call last):
  File "C:\Users\16946\Desktop\pythonProject\Auto_wed_current\Auto_base\wait.py", line 24, in wait_element
    WebDriverWait(self.driver, self.wait_time).until(EC.presence_of_all_elements_located((By.XPATH, self.xpath)))
  File "C:\Users\16946\Desktop\pythonProject\.venv\Lib\site-packages\selenium\webdriver\support\wait.py", line 105, in until
    raise TimeoutException(message, screen, stacktrace)
selenium.common.exceptions.TimeoutException: Message: 


During handling of the above exception, another exception occurred:

Traceback (most recent call last):
  File "C:\Users\16946\Desktop\pythonProject\Auto_wed_current\Auto_execute\execute_while.py", line 104, in execute_function_original
    driver_wait(row, xpath, account, error, self.wait_time, excel_file=self.excel_file, excel_sheet=excel_sheet).wait_element()
  File "C:\Users\16946\Desktop\pythonProject\Auto_wed_current\Auto_base\wait.py", line 26, in wait_element
    raise error_reminder('wait_element')
Auto_wed_current.Auto_base.error_reminder.error_reminder: [上传模板V1.0.xls]>[调试1]>[第2行]报错，页面等待超时

During handling of the above exception, another exception occurred:

Traceback (most recent call last):
  File "C:\Users\16946\Desktop\pythonProject\Auto_wed_current\Auto_execute\execute_while.py", line 137, in execute_function_original
    error_warning.error_screenshot()
  File "C:\Users\16946\Desktop\pythonProject\Auto_wed_current\Auto_base\error.py", line 26, in error_screenshot
    judge = setting_csv()
            ^^^^^^^^^^^^^
  File "C:\Users\16946\Desktop\pythonProject\Auto_wed_current\Auto_file\setting_csv.py", line 8, in setting_csv
    path = filename().filename(r'\Auto_file\配置文件\test_setting.csv')
           ^^^^^^^^^^^^^^^^^^^
AttributeError: 'filename' object has no attribute 'filename'

2024-09-01 23:36:37,159 - web_UI - ERROR - Traceback (most recent call last):
  File "C:\Users\16946\Desktop\pythonProject\Auto_wed_current\Auto_UI\web_qt_gui.py", line 77, in closeEvent
    driver.close()
  File "C:\Users\16946\Desktop\pythonProject\.venv\Lib\site-packages\selenium\webdriver\remote\webdriver.py", line 465, in close
    self.execute(Command.CLOSE)
  File "C:\Users\16946\Desktop\pythonProject\.venv\Lib\site-packages\selenium\webdriver\remote\webdriver.py", line 354, in execute
    self.error_handler.check_response(response)
  File "C:\Users\16946\Desktop\pythonProject\.venv\Lib\site-packages\selenium\webdriver\remote\errorhandler.py", line 229, in check_response
    raise exception_class(message, screen, stacktrace)
selenium.common.exceptions.WebDriverException: Message: disconnected: not connected to DevTools
  (failed to check if window was closed: disconnected: not connected to DevTools)
  (Session info: chrome=128.0.6613.114)
Stacktrace:
	GetHandleVerifier [0x00007FF6C108B632+29090]
	(No symbol) [0x00007FF6C0FFE6E9]
	(No symbol) [0x00007FF6C0EBB1CA]
	(No symbol) [0x00007FF6C0EA1296]
	(No symbol) [0x00007FF6C0EA231F]
	(No symbol) [0x00007FF6C0EBB7E3]
	(No symbol) [0x00007FF6C0E8F5ED]
	(No symbol) [0x00007FF6C0F45379]
	(No symbol) [0x00007FF6C0F366B0]
	(No symbol) [0x00007FF6C0F009B1]
	(No symbol) [0x00007FF6C0F01B11]
	GetHandleVerifier [0x00007FF6C13A883D+3294125]
	GetHandleVerifier [0x00007FF6C13F4423+3604371]
	GetHandleVerifier [0x00007FF6C13EA2E7+3563095]
	GetHandleVerifier [0x00007FF6C1146F16+797318]
	(No symbol) [0x00007FF6C100986F]
	(No symbol) [0x00007FF6C1005454]
	(No symbol) [0x00007FF6C10055E0]
	(No symbol) [0x00007FF6C0FF4A7F]
	BaseThreadInitThunk [0x00007FFF41E17374+20]
	RtlUserThreadStart [0x00007FFF43C3CC91+33]


2024-09-01 23:39:14,155 - web_UI - ERROR - Traceback (most recent call last):
  File "C:\Users\16946\Desktop\pythonProject\Auto_wed_current\Auto_base\wait.py", line 24, in wait_element
    WebDriverWait(self.driver, self.wait_time).until(EC.presence_of_all_elements_located((By.XPATH, self.xpath)))
  File "C:\Users\16946\Desktop\pythonProject\.venv\Lib\site-packages\selenium\webdriver\support\wait.py", line 105, in until
    raise TimeoutException(message, screen, stacktrace)
selenium.common.exceptions.TimeoutException: Message: 


During handling of the above exception, another exception occurred:

Traceback (most recent call last):
  File "C:\Users\16946\Desktop\pythonProject\Auto_wed_current\Auto_execute\execute_while.py", line 104, in execute_function_original
    driver_wait(row, xpath, account, error, self.wait_time, excel_file=self.excel_file, excel_sheet=excel_sheet).wait_element()
  File "C:\Users\16946\Desktop\pythonProject\Auto_wed_current\Auto_base\wait.py", line 26, in wait_element
    raise error_reminder('wait_element')
Auto_wed_current.Auto_base.error_reminder.error_reminder: [上传模板V1.0.xls]>[调试1]>[第2行]报错，页面等待超时

2024-09-01 23:42:30,645 - web_UI - ERROR - Traceback (most recent call last):
  File "C:\Users\16946\Desktop\pythonProject\Auto_wed_current\Auto_base\wait.py", line 24, in wait_element
    WebDriverWait(self.driver, self.wait_time).until(EC.presence_of_all_elements_located((By.XPATH, self.xpath)))
  File "C:\Users\16946\Desktop\pythonProject\.venv\Lib\site-packages\selenium\webdriver\support\wait.py", line 105, in until
    raise TimeoutException(message, screen, stacktrace)
selenium.common.exceptions.TimeoutException: Message: 


During handling of the above exception, another exception occurred:

Traceback (most recent call last):
  File "C:\Users\16946\Desktop\pythonProject\Auto_wed_current\Auto_execute\execute_while.py", line 104, in execute_function_original
    driver_wait(row, xpath, account, error, self.wait_time, excel_file=self.excel_file, excel_sheet=excel_sheet).wait_element()
  File "C:\Users\16946\Desktop\pythonProject\Auto_wed_current\Auto_base\wait.py", line 26, in wait_element
    raise error_reminder('wait_element')
Auto_wed_current.Auto_base.error_reminder.error_reminder: [上传模板V1.0.xls]>[调试1]>[第2行]报错，页面等待超时

2024-09-01 23:42:44,961 - web_UI - ERROR - Traceback (most recent call last):
  File "C:\Users\16946\Desktop\pythonProject\Auto_wed_current\Auto_UI\web_qt_gui.py", line 77, in closeEvent
    driver.close()
  File "C:\Users\16946\Desktop\pythonProject\.venv\Lib\site-packages\selenium\webdriver\remote\webdriver.py", line 465, in close
    self.execute(Command.CLOSE)
  File "C:\Users\16946\Desktop\pythonProject\.venv\Lib\site-packages\selenium\webdriver\remote\webdriver.py", line 354, in execute
    self.error_handler.check_response(response)
  File "C:\Users\16946\Desktop\pythonProject\.venv\Lib\site-packages\selenium\webdriver\remote\errorhandler.py", line 229, in check_response
    raise exception_class(message, screen, stacktrace)
selenium.common.exceptions.WebDriverException: Message: disconnected: not connected to DevTools
  (failed to check if window was closed: disconnected: not connected to DevTools)
  (Session info: chrome=128.0.6613.114)
Stacktrace:
	GetHandleVerifier [0x00007FF6C108B632+29090]
	(No symbol) [0x00007FF6C0FFE6E9]
	(No symbol) [0x00007FF6C0EBB1CA]
	(No symbol) [0x00007FF6C0EA1296]
	(No symbol) [0x00007FF6C0EA231F]
	(No symbol) [0x00007FF6C0EBB7E3]
	(No symbol) [0x00007FF6C0E8F5ED]
	(No symbol) [0x00007FF6C0F46497]
	(No symbol) [0x00007FF6C0F45A29]
	(No symbol) [0x00007FF6C0F366B0]
	(No symbol) [0x00007FF6C0F009B1]
	(No symbol) [0x00007FF6C0F01B11]
	GetHandleVerifier [0x00007FF6C13A883D+3294125]
	GetHandleVerifier [0x00007FF6C13F4423+3604371]
	GetHandleVerifier [0x00007FF6C13EA2E7+3563095]
	GetHandleVerifier [0x00007FF6C1146F16+797318]
	(No symbol) [0x00007FF6C100986F]
	(No symbol) [0x00007FF6C1005454]
	(No symbol) [0x00007FF6C10055E0]
	(No symbol) [0x00007FF6C0FF4A7F]
	BaseThreadInitThunk [0x00007FFF41E17374+20]
	RtlUserThreadStart [0x00007FFF43C3CC91+33]


2024-09-01 23:46:10,833 - web_UI - ERROR - Traceback (most recent call last):
  File "C:\Users\16946\Desktop\pythonProject\Auto_wed_current\Auto_base\wait.py", line 24, in wait_element
    WebDriverWait(self.driver, self.wait_time).until(EC.presence_of_all_elements_located((By.XPATH, self.xpath)))
  File "C:\Users\16946\Desktop\pythonProject\.venv\Lib\site-packages\selenium\webdriver\support\wait.py", line 105, in until
    raise TimeoutException(message, screen, stacktrace)
selenium.common.exceptions.TimeoutException: Message: 


During handling of the above exception, another exception occurred:

Traceback (most recent call last):
  File "C:\Users\16946\Desktop\pythonProject\Auto_wed_current\Auto_execute\execute_while.py", line 104, in execute_function_original
    driver_wait(row, xpath, account, error, self.wait_time, excel_file=self.excel_file, excel_sheet=excel_sheet).wait_element()
  File "C:\Users\16946\Desktop\pythonProject\Auto_wed_current\Auto_base\wait.py", line 26, in wait_element
    raise error_reminder('wait_element')
Auto_wed_current.Auto_base.error_reminder.error_reminder: [上传模板V1.0.xls]>[调试1]>[第2行]报错，页面等待超时

2024-09-01 23:48:18,792 - web_UI - ERROR - Traceback (most recent call last):
  File "C:\Users\16946\Desktop\pythonProject\Auto_wed_current\Auto_execute\execute_while.py", line 88, in execute_function_original
    action_judge(row, action, account, text, handles_get, text_dirt) # 最后执行操作
    ^^^^^^^^^^^^^^^^^^^^^^^^^^^^^^^^^^^^^^^^^^^^^^^^^^^^^^^^^^^^^^^^
  File "C:\Users\16946\Desktop\pythonProject\Auto_wed_current\Auto_carry\action.py", line 97, in action_judge
    driver.get(text)
  File "C:\Users\16946\Desktop\pythonProject\.venv\Lib\site-packages\selenium\webdriver\remote\webdriver.py", line 363, in get
    self.execute(Command.GET, {"url": url})
  File "C:\Users\16946\Desktop\pythonProject\.venv\Lib\site-packages\selenium\webdriver\remote\webdriver.py", line 354, in execute
    self.error_handler.check_response(response)
  File "C:\Users\16946\Desktop\pythonProject\.venv\Lib\site-packages\selenium\webdriver\remote\errorhandler.py", line 229, in check_response
    raise exception_class(message, screen, stacktrace)
selenium.common.exceptions.NoSuchWindowException: Message: no such window: target window already closed
from unknown error: web view not found
  (Session info: chrome=128.0.6613.114)
Stacktrace:
	GetHandleVerifier [0x00007FF6C108B632+29090]
	(No symbol) [0x00007FF6C0FFE6E9]
	(No symbol) [0x00007FF6C0EBB1CA]
	(No symbol) [0x00007FF6C0E8FAF5]
	(No symbol) [0x00007FF6C0F3E2E7]
	(No symbol) [0x00007FF6C0F55EE1]
	(No symbol) [0x00007FF6C0F36493]
	(No symbol) [0x00007FF6C0F009B1]
	(No symbol) [0x00007FF6C0F01B11]
	GetHandleVerifier [0x00007FF6C13A883D+3294125]
	GetHandleVerifier [0x00007FF6C13F4423+3604371]
	GetHandleVerifier [0x00007FF6C13EA2E7+3563095]
	GetHandleVerifier [0x00007FF6C1146F16+797318]
	(No symbol) [0x00007FF6C100986F]
	(No symbol) [0x00007FF6C1005454]
	(No symbol) [0x00007FF6C10055E0]
	(No symbol) [0x00007FF6C0FF4A7F]
	BaseThreadInitThunk [0x00007FFF41E17374+20]
	RtlUserThreadStart [0x00007FFF43C3CC91+33]


2024-09-01 23:52:50,619 - web_UI - ERROR - Traceback (most recent call last):
  File "C:\Users\16946\Desktop\pythonProject\Auto_wed_current\Auto_base\wait.py", line 24, in wait_element
    WebDriverWait(self.driver, self.wait_time).until(EC.presence_of_all_elements_located((By.XPATH, self.xpath)))
  File "C:\Users\16946\Desktop\pythonProject\.venv\Lib\site-packages\selenium\webdriver\support\wait.py", line 105, in until
    raise TimeoutException(message, screen, stacktrace)
selenium.common.exceptions.TimeoutException: Message: 


During handling of the above exception, another exception occurred:

Traceback (most recent call last):
  File "C:\Users\16946\Desktop\pythonProject\Auto_wed_current\Auto_execute\execute_while.py", line 104, in execute_function_original
    driver_wait(row, xpath, account, error, self.wait_time, excel_file=self.excel_file, excel_sheet=excel_sheet).wait_element()
  File "C:\Users\16946\Desktop\pythonProject\Auto_wed_current\Auto_base\wait.py", line 26, in wait_element
    raise error_reminder('wait_element')
Auto_wed_current.Auto_base.error_reminder.error_reminder: [上传模板V1.0.xls]>[调试1]>[第2行]报错，页面等待超时

2024-09-01 23:54:26,036 - web_UI - ERROR - Traceback (most recent call last):
  File "C:\Users\16946\Desktop\pythonProject\Auto_wed_current\Auto_execute\execute_while.py", line 76, in execute_function_original
    error_warning.error_action()# 【操作】数据验证报错提示
    ^^^^^^^^^^^^^^^^^^^^^^^^^^^^
  File "C:\Users\16946\Desktop\pythonProject\Auto_wed_current\Auto_base\error.py", line 98, in error_action
    raise error_reminder('error_action')
Auto_wed_current.Auto_base.error_reminder.error_reminder: [上传模板V1.0.xls]>[调试2]>[第1行]报错，请检查【操作】数据正确性

2024-09-01 23:55:34,109 - web_UI - ERROR - Traceback (most recent call last):
  File "C:\Users\16946\Desktop\pythonProject\Auto_wed_current\Auto_UI\web_qt_gui.py", line 77, in closeEvent
    driver.close()
  File "C:\Users\16946\Desktop\pythonProject\.venv\Lib\site-packages\selenium\webdriver\remote\webdriver.py", line 465, in close
    self.execute(Command.CLOSE)
  File "C:\Users\16946\Desktop\pythonProject\.venv\Lib\site-packages\selenium\webdriver\remote\webdriver.py", line 354, in execute
    self.error_handler.check_response(response)
  File "C:\Users\16946\Desktop\pythonProject\.venv\Lib\site-packages\selenium\webdriver\remote\errorhandler.py", line 229, in check_response
    raise exception_class(message, screen, stacktrace)
selenium.common.exceptions.WebDriverException: Message: disconnected: not connected to DevTools
  (failed to check if window was closed: disconnected: not connected to DevTools)
  (Session info: chrome=128.0.6613.114)
Stacktrace:
	GetHandleVerifier [0x00007FF6C108B632+29090]
	(No symbol) [0x00007FF6C0FFE6E9]
	(No symbol) [0x00007FF6C0EBB1CA]
	(No symbol) [0x00007FF6C0EA1296]
	(No symbol) [0x00007FF6C0EA231F]
	(No symbol) [0x00007FF6C0EBB7E3]
	(No symbol) [0x00007FF6C0E8F5ED]
	(No symbol) [0x00007FF6C0F46497]
	(No symbol) [0x00007FF6C0F45A29]
	(No symbol) [0x00007FF6C0F366B0]
	(No symbol) [0x00007FF6C0F009B1]
	(No symbol) [0x00007FF6C0F01B11]
	GetHandleVerifier [0x00007FF6C13A883D+3294125]
	GetHandleVerifier [0x00007FF6C13F4423+3604371]
	GetHandleVerifier [0x00007FF6C13EA2E7+3563095]
	GetHandleVerifier [0x00007FF6C1146F16+797318]
	(No symbol) [0x00007FF6C100986F]
	(No symbol) [0x00007FF6C1005454]
	(No symbol) [0x00007FF6C10055E0]
	(No symbol) [0x00007FF6C0FF4A7F]
	BaseThreadInitThunk [0x00007FFF41E17374+20]
	RtlUserThreadStart [0x00007FFF43C3CC91+33]


2024-09-02 09:23:21,251 - web_UI - ERROR - Traceback (most recent call last):
  File "C:\Users\16946\Desktop\pythonProject\Auto_wed_current\Auto_UI\GUI_Attachment\GUI_Thread_Attachment\thread_attachment_append.py", line 66, in run
    self.filedialog()
  File "C:\Users\16946\Desktop\pythonProject\Auto_wed_current\Auto_UI\GUI_Attachment\GUI_Thread_Attachment\thread_attachment_append.py", line 19, in filedialog
    dir.setFileMode(QFileDialog.ExistingFiles)  # 设置多选
                    ^^^^^^^^^^^^^^^^^^^^^^^^^
AttributeError: type object 'QFileDialog' has no attribute 'ExistingFiles'

2024-09-02 09:34:37,829 - web_UI - ERROR - Traceback (most recent call last):
  File "C:\Users\16946\Desktop\pythonProject\Auto_wed_current\Auto_UI\GUI_Attachment\GUI_Thread_Attachment\thread_attachment_append.py", line 66, in run
    self.filedialog()
  File "C:\Users\16946\Desktop\pythonProject\Auto_wed_current\Auto_UI\GUI_Attachment\GUI_Thread_Attachment\thread_attachment_append.py", line 23, in filedialog
    if dir.exec_():  # 判断是否选择了文件
       ^^^^^^^^^
AttributeError: 'QFileDialog' object has no attribute 'exec_'

2024-09-02 09:57:09,239 - web_UI - ERROR - Traceback (most recent call last):
  File "C:\Users\16946\Desktop\pythonProject\Auto_wed_current\Auto_UI\web_qt_gui.py", line 77, in closeEvent
    driver.close()
    ^^^^^^
  File "_pydevd_bundle\\pydevd_cython_win32_311_64.pyx", line 1187, in _pydevd_bundle.pydevd_cython_win32_311_64.SafeCallWrapper.__call__
  File "_pydevd_bundle\\pydevd_cython_win32_311_64.pyx", line 627, in _pydevd_bundle.pydevd_cython_win32_311_64.PyDBFrame.trace_dispatch
  File "_pydevd_bundle\\pydevd_cython_win32_311_64.pyx", line 937, in _pydevd_bundle.pydevd_cython_win32_311_64.PyDBFrame.trace_dispatch
  File "_pydevd_bundle\\pydevd_cython_win32_311_64.pyx", line 928, in _pydevd_bundle.pydevd_cython_win32_311_64.PyDBFrame.trace_dispatch
  File "_pydevd_bundle\\pydevd_cython_win32_311_64.pyx", line 585, in _pydevd_bundle.pydevd_cython_win32_311_64.PyDBFrame.do_wait_suspend
  File "C:\Program Files\JetBrains\PyCharm 2024.2.0.1\plugins\python-ce\helpers\pydev\pydevd.py", line 1207, in do_wait_suspend
    self._do_wait_suspend(thread, frame, event, arg, suspend_type, from_this_thread)
  File "C:\Program Files\JetBrains\PyCharm 2024.2.0.1\plugins\python-ce\helpers\pydev\pydevd.py", line 1222, in _do_wait_suspend
    time.sleep(0.01)
KeyboardInterrupt

2024-09-02 10:56:31,433 - web_UI - ERROR - Traceback (most recent call last):
  File "C:\Users\16946\AppData\Local\Programs\Python\Python311\Lib\enum.py", line 688, in __call__
    def __call__(cls, value, names=None, *, module=None, qualname=None, type=None, start=1, boundary=None):
    
KeyboardInterrupt

2024-09-02 10:57:23,437 - web_UI - ERROR - Traceback (most recent call last):
  File "C:\Users\16946\AppData\Local\Programs\Python\Python311\Lib\enum.py", line 688, in __call__
    def __call__(cls, value, names=None, *, module=None, qualname=None, type=None, start=1, boundary=None):
    
KeyboardInterrupt

2024-09-02 18:18:02,476 - web_UI - ERROR - Traceback (most recent call last):
  File "C:\Users\16946\Desktop\pythonProject\Auto_wed_current\Auto_UI\GUI_Template\GIU_Template_File\append_file.py", line 15, in original_file
    self.thread = thread_template_append(self.listWidget_original, condition)
                  ^^^^^^^^^^^^^^^^^^^^^^^^^^^^^^^^^^^^^^^^^^^^^^^^^^^^^^^^^^^
  File "C:\Users\16946\Desktop\pythonProject\Auto_wed_current\Auto_UI\GUI_Template\GUI_Template_Thread\thread_template_append.py", line 10, in __init__
    super(self).__init__() # QThread,
    ^^^^^^^^^^^
TypeError: super() argument 1 must be a type, not thread_template_append

2024-09-02 18:18:46,644 - web_UI - ERROR - Traceback (most recent call last):
  File "C:\Users\16946\AppData\Local\Programs\Python\Python311\Lib\enum.py", line 688, in __call__
    def __call__(cls, value, names=None, *, module=None, qualname=None, type=None, start=1, boundary=None):
    
KeyboardInterrupt

2024-09-02 18:18:55,279 - web_UI - ERROR - Traceback (most recent call last):
  File "C:\Users\16946\Desktop\pythonProject\Auto_wed_current\Auto_UI\GUI_Template\GIU_Template_File\append_file.py", line 17, in original_file
    self.thread.dialog_box()
    ^^^^^^^^^^^^^^^^^^^^^^
TypeError: thread_template_append cannot be converted to PyQt6.QtCore.QObject

2024-09-02 18:19:35,091 - web_UI - ERROR - Traceback (most recent call last):
  File "C:\Users\16946\AppData\Local\Programs\Python\Python311\Lib\enum.py", line 688, in __call__
    def __call__(cls, value, names=None, *, module=None, qualname=None, type=None, start=1, boundary=None):
    
KeyboardInterrupt

2024-09-02 18:19:46,880 - web_UI - ERROR - Traceback (most recent call last):
  File "C:\Users\16946\Desktop\pythonProject\Auto_wed_current\Auto_UI\GUI_Template\GIU_Template_File\append_file.py", line 17, in original_file
    self.thread.dialog_box()
    ^^^^^^^^^^^^^^^^^^^^^^
TypeError: thread_template_append cannot be converted to PyQt6.QtCore.QObject

2024-09-02 18:20:12,333 - web_UI - ERROR - Traceback (most recent call last):
  File "C:\Users\16946\AppData\Local\Programs\Python\Python311\Lib\enum.py", line 688, in __call__
    def __call__(cls, value, names=None, *, module=None, qualname=None, type=None, start=1, boundary=None):
    
KeyboardInterrupt

2024-09-02 18:20:31,809 - web_UI - ERROR - Traceback (most recent call last):
  File "C:\Users\16946\Desktop\pythonProject\Auto_wed_current\Auto_UI\GUI_Template\GIU_Template_File\append_file.py", line 17, in original_file
    self.thread.dialog_box()
    ^^^^^^^^^^^^^^^^^^^^^^
TypeError: thread_template_append cannot be converted to PyQt6.QtCore.QObject

2024-09-02 18:23:42,594 - web_UI - ERROR - Traceback (most recent call last):
  File "C:\Users\16946\Desktop\pythonProject\Auto_wed_current\Auto_UI\GUI_Template\GIU_Template_File\append_file.py", line 17, in original_file
    self.thread.dialog_box()
    ^^^^^^^^^^^^^^^^^^^^^^
TypeError: thread_template_append cannot be converted to PyQt6.QtCore.QObject

2024-09-02 18:25:08,703 - web_UI - ERROR - Traceback (most recent call last):
  File "C:\Users\16946\Desktop\pythonProject\Auto_wed_current\Auto_UI\GUI_Template\GIU_Template_File\append_file.py", line 17, in original_file
    thread_template_append(self.listWidget_original, condition).dialog_box()
    ^^^^^^^^^^^^^^^^^^^^^^^^^^^^^^^^^^^^^^^^^^^^^^^^^^^^^^^^^^^^^^^^^^^^^^
AttributeError: 'thread_template_append' object has no attribute 'dialog_box'

2024-09-02 18:32:52,476 - web_UI - ERROR - Traceback (most recent call last):
  File "C:\Users\16946\AppData\Local\Programs\Python\Python311\Lib\enum.py", line 688, in __call__
    def __call__(cls, value, names=None, *, module=None, qualname=None, type=None, start=1, boundary=None):
    
KeyboardInterrupt

2024-09-02 18:33:06,641 - web_UI - ERROR - Traceback (most recent call last):
  File "C:\Users\16946\Desktop\pythonProject\Auto_wed_current\Auto_UI\GUI_Template\GIU_Template_File\append_file.py", line 18, in original_file
    thread_template.dialog_box.connect(self.QMessageBox_error)
    ^^^^^^^^^^^^^^^^^^^^^^^^^^
AttributeError: 'NoneType' object has no attribute 'dialog_box'

2024-09-02 18:33:09,702 - web_UI - ERROR - Traceback (most recent call last):
  File "C:\Users\16946\Desktop\pythonProject\Auto_wed_current\Auto_UI\GUI_Template\GUI_Template_Perform\web_template_perform.py", line 90, in template_confirm
    self.cb.del_template()  # 取至web_perform_func
    ^^^^^^^^^^^^^^^^^^^^
AttributeError: 'web_combobox' object has no attribute 'del_template'

2024-09-02 18:36:28,803 - web_UI - ERROR - Traceback (most recent call last):
  File "C:\Users\16946\Desktop\pythonProject\Auto_wed_current\Auto_UI\GUI_Template\GIU_Template_File\append_file.py", line 17, in original_file
    thread_template = thread_template_append(self.listWidget_original, condition).filedialog()
                      ^^^^^^^^^^^^^^^^^^^^^^^^^^^^^^^^^^^^^^^^^^^^^^^^^^^^^^^^^^^^^^^^^^^^^^^^
  File "C:\Users\16946\Desktop\pythonProject\Auto_wed_current\Auto_UI\GUI_Template\GUI_Template_Thread\thread_template_append.py", line 36, in filedialog
    num -= 1
    ^^^
  File "_pydevd_bundle\\pydevd_cython_win32_311_64.pyx", line 1187, in _pydevd_bundle.pydevd_cython_win32_311_64.SafeCallWrapper.__call__
  File "_pydevd_bundle\\pydevd_cython_win32_311_64.pyx", line 627, in _pydevd_bundle.pydevd_cython_win32_311_64.PyDBFrame.trace_dispatch
  File "_pydevd_bundle\\pydevd_cython_win32_311_64.pyx", line 1103, in _pydevd_bundle.pydevd_cython_win32_311_64.PyDBFrame.trace_dispatch
  File "_pydevd_bundle\\pydevd_cython_win32_311_64.pyx", line 1065, in _pydevd_bundle.pydevd_cython_win32_311_64.PyDBFrame.trace_dispatch
  File "_pydevd_bundle\\pydevd_cython_win32_311_64.pyx", line 585, in _pydevd_bundle.pydevd_cython_win32_311_64.PyDBFrame.do_wait_suspend
  File "C:\Program Files\JetBrains\PyCharm 2024.2.0.1\plugins\python-ce\helpers\pydev\pydevd.py", line 1207, in do_wait_suspend
    self._do_wait_suspend(thread, frame, event, arg, suspend_type, from_this_thread)
  File "C:\Program Files\JetBrains\PyCharm 2024.2.0.1\plugins\python-ce\helpers\pydev\pydevd.py", line 1222, in _do_wait_suspend
    time.sleep(0.01)
KeyboardInterrupt

2024-09-02 20:10:08,878 - web_UI - ERROR - Traceback (most recent call last):
  File "C:\Users\16946\Desktop\pythonProject\Auto_wed_current\Auto_UI\GUI_Template\GIU_Template_File\append_file.py", line 18, in original_file
    thread_template.dialog_box.connect(self.QMessageBox_error)
    ^^^^^^^^^^^^^^^^^^^^^^^^^^
AttributeError: 'NoneType' object has no attribute 'dialog_box'

2024-09-02 20:15:04,329 - web_UI - ERROR - Traceback (most recent call last):
  File "C:\Users\16946\Desktop\pythonProject\Auto_wed_current\Auto_UI\GUI_Template\GIU_Template_File\append_file.py", line 18, in original_file
    thread_template.dialog_box.connect(self.QMessageBox_error)
    ^^^^^^^^^^^^^^^^^^^^^^^^^^
AttributeError: 'NoneType' object has no attribute 'dialog_box'

2024-09-02 20:15:06,859 - web_UI - ERROR - Traceback (most recent call last):
  File "C:\Users\16946\Desktop\pythonProject\Auto_wed_current\Auto_UI\GUI_Template\GUI_Template_Perform\web_template_perform.py", line 90, in template_confirm
    self.cb.del_template()  # 取至web_perform_func
    ^^^^^^^^^^^^^^^^^^^^
AttributeError: 'web_combobox' object has no attribute 'del_template'

2024-09-02 20:18:23,772 - web_UI - ERROR - Traceback (most recent call last):
  File "C:\Users\16946\Desktop\pythonProject\Auto_wed_current\Auto_UI\GUI_Template\GIU_Template_File\append_file.py", line 13, in original_file
    thread_template.dialog_box.connect(self.QMessageBox_error)
    ^^^^^^^^^^^^^^^^^^^^^^^^^^
AttributeError: 'NoneType' object has no attribute 'dialog_box'

2024-09-02 20:30:35,716 - web_UI - ERROR - Traceback (most recent call last):
  File "C:\Users\16946\Desktop\pythonProject\Auto_wed_current\Auto_UI\GUI_Template\GIU_Template_File\append_file.py", line 12, in original_file
    thread_template_append(self.listWidget_original, condition).filedialog()
  File "C:\Users\16946\Desktop\pythonProject\Auto_wed_current\Auto_UI\GUI_Template\GUI_Template_Thread\thread_template_append.py", line 25, in filedialog
    listWidget_data = []
                      ^^
  File "_pydevd_bundle\\pydevd_cython_win32_311_64.pyx", line 1187, in _pydevd_bundle.pydevd_cython_win32_311_64.SafeCallWrapper.__call__
  File "_pydevd_bundle\\pydevd_cython_win32_311_64.pyx", line 627, in _pydevd_bundle.pydevd_cython_win32_311_64.PyDBFrame.trace_dispatch
  File "_pydevd_bundle\\pydevd_cython_win32_311_64.pyx", line 1103, in _pydevd_bundle.pydevd_cython_win32_311_64.PyDBFrame.trace_dispatch
  File "_pydevd_bundle\\pydevd_cython_win32_311_64.pyx", line 1065, in _pydevd_bundle.pydevd_cython_win32_311_64.PyDBFrame.trace_dispatch
  File "_pydevd_bundle\\pydevd_cython_win32_311_64.pyx", line 585, in _pydevd_bundle.pydevd_cython_win32_311_64.PyDBFrame.do_wait_suspend
  File "C:\Program Files\JetBrains\PyCharm 2024.2.0.1\plugins\python-ce\helpers\pydev\pydevd.py", line 1207, in do_wait_suspend
    self._do_wait_suspend(thread, frame, event, arg, suspend_type, from_this_thread)
  File "C:\Program Files\JetBrains\PyCharm 2024.2.0.1\plugins\python-ce\helpers\pydev\pydevd.py", line 1222, in _do_wait_suspend
    time.sleep(0.01)
KeyboardInterrupt

2024-09-02 20:35:04,731 - web_UI - ERROR - Traceback (most recent call last):
  File "C:\Users\16946\AppData\Local\Programs\Python\Python311\Lib\enum.py", line 688, in __call__
    def __call__(cls, value, names=None, *, module=None, qualname=None, type=None, start=1, boundary=None):
    
KeyboardInterrupt

2024-09-02 20:35:26,742 - web_UI - ERROR - Traceback (most recent call last):
  File "C:\Users\16946\Desktop\pythonProject\Auto_wed_current\Auto_UI\GUI_Template\GIU_Template_File\append_file.py", line 12, in original_file
    thread_template_append(self.listWidget_original, condition).filedialog()
  File "C:\Users\16946\Desktop\pythonProject\Auto_wed_current\Auto_UI\GUI_Template\GUI_Template_Thread\thread_template_append.py", line 24, in filedialog
    return
  File "_pydevd_bundle\\pydevd_cython_win32_311_64.pyx", line 1187, in _pydevd_bundle.pydevd_cython_win32_311_64.SafeCallWrapper.__call__
  File "_pydevd_bundle\\pydevd_cython_win32_311_64.pyx", line 627, in _pydevd_bundle.pydevd_cython_win32_311_64.PyDBFrame.trace_dispatch
  File "_pydevd_bundle\\pydevd_cython_win32_311_64.pyx", line 1103, in _pydevd_bundle.pydevd_cython_win32_311_64.PyDBFrame.trace_dispatch
  File "_pydevd_bundle\\pydevd_cython_win32_311_64.pyx", line 1065, in _pydevd_bundle.pydevd_cython_win32_311_64.PyDBFrame.trace_dispatch
  File "_pydevd_bundle\\pydevd_cython_win32_311_64.pyx", line 585, in _pydevd_bundle.pydevd_cython_win32_311_64.PyDBFrame.do_wait_suspend
  File "C:\Program Files\JetBrains\PyCharm 2024.2.0.1\plugins\python-ce\helpers\pydev\pydevd.py", line 1207, in do_wait_suspend
    self._do_wait_suspend(thread, frame, event, arg, suspend_type, from_this_thread)
  File "C:\Program Files\JetBrains\PyCharm 2024.2.0.1\plugins\python-ce\helpers\pydev\pydevd.py", line 1222, in _do_wait_suspend
    time.sleep(0.01)
KeyboardInterrupt

2024-09-02 20:35:47,227 - web_UI - ERROR - Traceback (most recent call last):
  File "C:\Users\16946\Desktop\pythonProject\Auto_wed_current\Auto_UI\GUI_Template\GIU_Template_File\append_file.py", line 12, in original_file
    thread_template_append(self.listWidget_original, condition).filedialog()
  File "C:\Users\16946\Desktop\pythonProject\Auto_wed_current\Auto_UI\GUI_Template\GUI_Template_Thread\thread_template_append.py", line 38, in filedialog
    self.listWidget.addItems(filename_list)
TypeError: index 0 has type 'QUrl' but 'str' is expected

2024-09-02 20:39:17,059 - web_UI - ERROR - Traceback (most recent call last):
  File "C:\Users\16946\Desktop\pythonProject\Auto_wed_current\Auto_UI\GUI_Template\GIU_Template_File\append_file.py", line 12, in original_file
    thread_template_append(self.listWidget_original, condition).filedialog()
  File "C:\Users\16946\Desktop\pythonProject\Auto_wed_current\Auto_UI\GUI_Template\GUI_Template_Thread\thread_template_append.py", line 26, in filedialog
    listWidget_data = []
                      ^^
  File "_pydevd_bundle\\pydevd_cython_win32_311_64.pyx", line 1187, in _pydevd_bundle.pydevd_cython_win32_311_64.SafeCallWrapper.__call__
  File "_pydevd_bundle\\pydevd_cython_win32_311_64.pyx", line 627, in _pydevd_bundle.pydevd_cython_win32_311_64.PyDBFrame.trace_dispatch
  File "_pydevd_bundle\\pydevd_cython_win32_311_64.pyx", line 1103, in _pydevd_bundle.pydevd_cython_win32_311_64.PyDBFrame.trace_dispatch
  File "_pydevd_bundle\\pydevd_cython_win32_311_64.pyx", line 1065, in _pydevd_bundle.pydevd_cython_win32_311_64.PyDBFrame.trace_dispatch
  File "_pydevd_bundle\\pydevd_cython_win32_311_64.pyx", line 585, in _pydevd_bundle.pydevd_cython_win32_311_64.PyDBFrame.do_wait_suspend
  File "C:\Program Files\JetBrains\PyCharm 2024.2.0.1\plugins\python-ce\helpers\pydev\pydevd.py", line 1207, in do_wait_suspend
    self._do_wait_suspend(thread, frame, event, arg, suspend_type, from_this_thread)
  File "C:\Program Files\JetBrains\PyCharm 2024.2.0.1\plugins\python-ce\helpers\pydev\pydevd.py", line 1222, in _do_wait_suspend
    time.sleep(0.01)
KeyboardInterrupt

2024-09-02 20:39:51,552 - web_UI - ERROR - Traceback (most recent call last):
  File "C:\Users\16946\Desktop\pythonProject\Auto_wed_current\Auto_UI\GUI_Template\GIU_Template_File\append_file.py", line 12, in original_file
    thread_template_append(self.listWidget_original, condition).filedialog()
  File "C:\Users\16946\Desktop\pythonProject\Auto_wed_current\Auto_UI\GUI_Template\GUI_Template_Thread\thread_template_append.py", line 26, in filedialog
    listWidget_data = []
                      ^^
  File "_pydevd_bundle\\pydevd_cython_win32_311_64.pyx", line 1187, in _pydevd_bundle.pydevd_cython_win32_311_64.SafeCallWrapper.__call__
  File "_pydevd_bundle\\pydevd_cython_win32_311_64.pyx", line 627, in _pydevd_bundle.pydevd_cython_win32_311_64.PyDBFrame.trace_dispatch
  File "_pydevd_bundle\\pydevd_cython_win32_311_64.pyx", line 1103, in _pydevd_bundle.pydevd_cython_win32_311_64.PyDBFrame.trace_dispatch
  File "_pydevd_bundle\\pydevd_cython_win32_311_64.pyx", line 1065, in _pydevd_bundle.pydevd_cython_win32_311_64.PyDBFrame.trace_dispatch
  File "_pydevd_bundle\\pydevd_cython_win32_311_64.pyx", line 585, in _pydevd_bundle.pydevd_cython_win32_311_64.PyDBFrame.do_wait_suspend
  File "C:\Program Files\JetBrains\PyCharm 2024.2.0.1\plugins\python-ce\helpers\pydev\pydevd.py", line 1207, in do_wait_suspend
    self._do_wait_suspend(thread, frame, event, arg, suspend_type, from_this_thread)
  File "C:\Program Files\JetBrains\PyCharm 2024.2.0.1\plugins\python-ce\helpers\pydev\pydevd.py", line 1222, in _do_wait_suspend
    time.sleep(0.01)
KeyboardInterrupt

2024-09-02 20:41:31,510 - web_UI - ERROR - Traceback (most recent call last):
  File "C:\Users\16946\Desktop\pythonProject\Auto_wed_current\Auto_UI\GUI_Template\GIU_Template_File\append_file.py", line 12, in original_file
    thread_template_append(self.listWidget_original, condition).filedialog()
  File "C:\Users\16946\Desktop\pythonProject\Auto_wed_current\Auto_UI\GUI_Template\GUI_Template_Thread\thread_template_append.py", line 26, in filedialog
    listWidget_data = []
                      ^^
  File "_pydevd_bundle\\pydevd_cython_win32_311_64.pyx", line 1187, in _pydevd_bundle.pydevd_cython_win32_311_64.SafeCallWrapper.__call__
  File "_pydevd_bundle\\pydevd_cython_win32_311_64.pyx", line 627, in _pydevd_bundle.pydevd_cython_win32_311_64.PyDBFrame.trace_dispatch
  File "_pydevd_bundle\\pydevd_cython_win32_311_64.pyx", line 1103, in _pydevd_bundle.pydevd_cython_win32_311_64.PyDBFrame.trace_dispatch
  File "_pydevd_bundle\\pydevd_cython_win32_311_64.pyx", line 1065, in _pydevd_bundle.pydevd_cython_win32_311_64.PyDBFrame.trace_dispatch
  File "_pydevd_bundle\\pydevd_cython_win32_311_64.pyx", line 585, in _pydevd_bundle.pydevd_cython_win32_311_64.PyDBFrame.do_wait_suspend
  File "C:\Program Files\JetBrains\PyCharm 2024.2.0.1\plugins\python-ce\helpers\pydev\pydevd.py", line 1207, in do_wait_suspend
    self._do_wait_suspend(thread, frame, event, arg, suspend_type, from_this_thread)
  File "C:\Program Files\JetBrains\PyCharm 2024.2.0.1\plugins\python-ce\helpers\pydev\pydevd.py", line 1222, in _do_wait_suspend
    time.sleep(0.01)
KeyboardInterrupt

2024-09-02 20:42:06,297 - web_UI - ERROR - Traceback (most recent call last):
  File "C:\Users\16946\Desktop\pythonProject\Auto_wed_current\Auto_UI\GUI_Template\GIU_Template_File\append_file.py", line 12, in original_file
    thread_template_append(self.listWidget_original, condition).filedialog()
  File "C:\Users\16946\Desktop\pythonProject\Auto_wed_current\Auto_UI\GUI_Template\GUI_Template_Thread\thread_template_append.py", line 26, in filedialog
    listWidget_data = []
                      ^^
  File "_pydevd_bundle\\pydevd_cython_win32_311_64.pyx", line 1187, in _pydevd_bundle.pydevd_cython_win32_311_64.SafeCallWrapper.__call__
  File "_pydevd_bundle\\pydevd_cython_win32_311_64.pyx", line 627, in _pydevd_bundle.pydevd_cython_win32_311_64.PyDBFrame.trace_dispatch
  File "_pydevd_bundle\\pydevd_cython_win32_311_64.pyx", line 1103, in _pydevd_bundle.pydevd_cython_win32_311_64.PyDBFrame.trace_dispatch
  File "_pydevd_bundle\\pydevd_cython_win32_311_64.pyx", line 1065, in _pydevd_bundle.pydevd_cython_win32_311_64.PyDBFrame.trace_dispatch
  File "_pydevd_bundle\\pydevd_cython_win32_311_64.pyx", line 585, in _pydevd_bundle.pydevd_cython_win32_311_64.PyDBFrame.do_wait_suspend
  File "C:\Program Files\JetBrains\PyCharm 2024.2.0.1\plugins\python-ce\helpers\pydev\pydevd.py", line 1207, in do_wait_suspend
    self._do_wait_suspend(thread, frame, event, arg, suspend_type, from_this_thread)
  File "C:\Program Files\JetBrains\PyCharm 2024.2.0.1\plugins\python-ce\helpers\pydev\pydevd.py", line 1222, in _do_wait_suspend
    time.sleep(0.01)
KeyboardInterrupt

2024-09-02 20:42:35,361 - web_UI - ERROR - Traceback (most recent call last):
  File "C:\Users\16946\Desktop\pythonProject\Auto_wed_current\Auto_UI\GUI_Template\GIU_Template_File\append_file.py", line 12, in original_file
    thread_template_append(self.listWidget_original, condition).filedialog()
  File "C:\Users\16946\Desktop\pythonProject\Auto_wed_current\Auto_UI\GUI_Template\GUI_Template_Thread\thread_template_append.py", line 23, in filedialog
    if len(list(filename_list)) == 1:
       ^^^
  File "_pydevd_bundle\\pydevd_cython_win32_311_64.pyx", line 1187, in _pydevd_bundle.pydevd_cython_win32_311_64.SafeCallWrapper.__call__
  File "_pydevd_bundle\\pydevd_cython_win32_311_64.pyx", line 627, in _pydevd_bundle.pydevd_cython_win32_311_64.PyDBFrame.trace_dispatch
  File "_pydevd_bundle\\pydevd_cython_win32_311_64.pyx", line 937, in _pydevd_bundle.pydevd_cython_win32_311_64.PyDBFrame.trace_dispatch
  File "_pydevd_bundle\\pydevd_cython_win32_311_64.pyx", line 928, in _pydevd_bundle.pydevd_cython_win32_311_64.PyDBFrame.trace_dispatch
  File "_pydevd_bundle\\pydevd_cython_win32_311_64.pyx", line 585, in _pydevd_bundle.pydevd_cython_win32_311_64.PyDBFrame.do_wait_suspend
  File "C:\Program Files\JetBrains\PyCharm 2024.2.0.1\plugins\python-ce\helpers\pydev\pydevd.py", line 1207, in do_wait_suspend
    self._do_wait_suspend(thread, frame, event, arg, suspend_type, from_this_thread)
  File "C:\Program Files\JetBrains\PyCharm 2024.2.0.1\plugins\python-ce\helpers\pydev\pydevd.py", line 1222, in _do_wait_suspend
    time.sleep(0.01)
KeyboardInterrupt

2024-09-02 20:44:17,812 - web_UI - ERROR - Traceback (most recent call last):
  File "C:\Users\16946\Desktop\pythonProject\Auto_wed_current\Auto_UI\GUI_Template\GIU_Template_File\append_file.py", line 12, in original_file
    thread_template_append(self.listWidget_original, condition).filedialog()
  File "C:\Users\16946\Desktop\pythonProject\Auto_wed_current\Auto_UI\GUI_Template\GUI_Template_Thread\thread_template_append.py", line 26, in filedialog
    listWidget_data = []
                      ^^
  File "_pydevd_bundle\\pydevd_cython_win32_311_64.pyx", line 1187, in _pydevd_bundle.pydevd_cython_win32_311_64.SafeCallWrapper.__call__
  File "_pydevd_bundle\\pydevd_cython_win32_311_64.pyx", line 627, in _pydevd_bundle.pydevd_cython_win32_311_64.PyDBFrame.trace_dispatch
  File "_pydevd_bundle\\pydevd_cython_win32_311_64.pyx", line 1103, in _pydevd_bundle.pydevd_cython_win32_311_64.PyDBFrame.trace_dispatch
  File "_pydevd_bundle\\pydevd_cython_win32_311_64.pyx", line 1065, in _pydevd_bundle.pydevd_cython_win32_311_64.PyDBFrame.trace_dispatch
  File "_pydevd_bundle\\pydevd_cython_win32_311_64.pyx", line 585, in _pydevd_bundle.pydevd_cython_win32_311_64.PyDBFrame.do_wait_suspend
  File "C:\Program Files\JetBrains\PyCharm 2024.2.0.1\plugins\python-ce\helpers\pydev\pydevd.py", line 1207, in do_wait_suspend
    self._do_wait_suspend(thread, frame, event, arg, suspend_type, from_this_thread)
  File "C:\Program Files\JetBrains\PyCharm 2024.2.0.1\plugins\python-ce\helpers\pydev\pydevd.py", line 1222, in _do_wait_suspend
    time.sleep(0.01)
KeyboardInterrupt

2024-09-02 20:44:37,656 - web_UI - ERROR - Traceback (most recent call last):
  File "C:\Users\16946\Desktop\pythonProject\Auto_wed_current\Auto_UI\GUI_Template\GIU_Template_File\append_file.py", line 12, in original_file
    thread_template_append(self.listWidget_original, condition).filedialog()
  File "C:\Users\16946\Desktop\pythonProject\Auto_wed_current\Auto_UI\GUI_Template\GUI_Template_Thread\thread_template_append.py", line 23, in filedialog
    if len(filename_list) == 0:
       ^^^
  File "_pydevd_bundle\\pydevd_cython_win32_311_64.pyx", line 1187, in _pydevd_bundle.pydevd_cython_win32_311_64.SafeCallWrapper.__call__
  File "_pydevd_bundle\\pydevd_cython_win32_311_64.pyx", line 627, in _pydevd_bundle.pydevd_cython_win32_311_64.PyDBFrame.trace_dispatch
  File "_pydevd_bundle\\pydevd_cython_win32_311_64.pyx", line 937, in _pydevd_bundle.pydevd_cython_win32_311_64.PyDBFrame.trace_dispatch
  File "_pydevd_bundle\\pydevd_cython_win32_311_64.pyx", line 928, in _pydevd_bundle.pydevd_cython_win32_311_64.PyDBFrame.trace_dispatch
  File "_pydevd_bundle\\pydevd_cython_win32_311_64.pyx", line 585, in _pydevd_bundle.pydevd_cython_win32_311_64.PyDBFrame.do_wait_suspend
  File "C:\Program Files\JetBrains\PyCharm 2024.2.0.1\plugins\python-ce\helpers\pydev\pydevd.py", line 1207, in do_wait_suspend
    self._do_wait_suspend(thread, frame, event, arg, suspend_type, from_this_thread)
  File "C:\Program Files\JetBrains\PyCharm 2024.2.0.1\plugins\python-ce\helpers\pydev\pydevd.py", line 1222, in _do_wait_suspend
    time.sleep(0.01)
KeyboardInterrupt

2024-09-02 20:48:46,105 - web_UI - ERROR - Traceback (most recent call last):
  File "C:\Users\16946\Desktop\pythonProject\Auto_wed_current\Auto_UI\GUI_Template\GIU_Template_File\append_file.py", line 12, in original_file
    thread_template_append(self.listWidget_original, condition).filedialog()
  File "C:\Users\16946\Desktop\pythonProject\Auto_wed_current\Auto_UI\GUI_Template\GUI_Template_Thread\thread_template_append.py", line 32, in filedialog
    if filename in listWidget_data:
       ^^^^^^^^
  File "_pydevd_bundle\\pydevd_cython_win32_311_64.pyx", line 1187, in _pydevd_bundle.pydevd_cython_win32_311_64.SafeCallWrapper.__call__
  File "_pydevd_bundle\\pydevd_cython_win32_311_64.pyx", line 627, in _pydevd_bundle.pydevd_cython_win32_311_64.PyDBFrame.trace_dispatch
  File "_pydevd_bundle\\pydevd_cython_win32_311_64.pyx", line 1103, in _pydevd_bundle.pydevd_cython_win32_311_64.PyDBFrame.trace_dispatch
  File "_pydevd_bundle\\pydevd_cython_win32_311_64.pyx", line 1065, in _pydevd_bundle.pydevd_cython_win32_311_64.PyDBFrame.trace_dispatch
  File "_pydevd_bundle\\pydevd_cython_win32_311_64.pyx", line 585, in _pydevd_bundle.pydevd_cython_win32_311_64.PyDBFrame.do_wait_suspend
  File "C:\Program Files\JetBrains\PyCharm 2024.2.0.1\plugins\python-ce\helpers\pydev\pydevd.py", line 1207, in do_wait_suspend
    self._do_wait_suspend(thread, frame, event, arg, suspend_type, from_this_thread)
  File "C:\Program Files\JetBrains\PyCharm 2024.2.0.1\plugins\python-ce\helpers\pydev\pydevd.py", line 1222, in _do_wait_suspend
    time.sleep(0.01)
KeyboardInterrupt

2024-09-02 20:50:00,267 - web_UI - ERROR - Traceback (most recent call last):
  File "C:\Users\16946\Desktop\pythonProject\Auto_wed_current\Auto_UI\GUI_Template\GIU_Template_File\append_file.py", line 12, in original_file
    thread_template_append(self.listWidget_original, condition).filedialog()
  File "C:\Users\16946\Desktop\pythonProject\Auto_wed_current\Auto_UI\GUI_Template\GUI_Template_Thread\thread_template_append.py", line 27, in filedialog
    filename_list = [] # 文件名列表
              ^^^
  File "_pydevd_bundle\\pydevd_cython_win32_311_64.pyx", line 1187, in _pydevd_bundle.pydevd_cython_win32_311_64.SafeCallWrapper.__call__
  File "_pydevd_bundle\\pydevd_cython_win32_311_64.pyx", line 627, in _pydevd_bundle.pydevd_cython_win32_311_64.PyDBFrame.trace_dispatch
  File "_pydevd_bundle\\pydevd_cython_win32_311_64.pyx", line 1103, in _pydevd_bundle.pydevd_cython_win32_311_64.PyDBFrame.trace_dispatch
  File "_pydevd_bundle\\pydevd_cython_win32_311_64.pyx", line 1065, in _pydevd_bundle.pydevd_cython_win32_311_64.PyDBFrame.trace_dispatch
  File "_pydevd_bundle\\pydevd_cython_win32_311_64.pyx", line 585, in _pydevd_bundle.pydevd_cython_win32_311_64.PyDBFrame.do_wait_suspend
  File "C:\Program Files\JetBrains\PyCharm 2024.2.0.1\plugins\python-ce\helpers\pydev\pydevd.py", line 1207, in do_wait_suspend
    self._do_wait_suspend(thread, frame, event, arg, suspend_type, from_this_thread)
  File "C:\Program Files\JetBrains\PyCharm 2024.2.0.1\plugins\python-ce\helpers\pydev\pydevd.py", line 1222, in _do_wait_suspend
    time.sleep(0.01)
KeyboardInterrupt

2024-09-02 20:54:14,828 - web_UI - ERROR - Traceback (most recent call last):
  File "C:\Users\16946\Desktop\pythonProject\Auto_wed_current\Auto_UI\GUI_Template\GIU_Template_File\append_file.py", line 10, in original_file
    def original_file(self):
    
KeyboardInterrupt

2024-09-02 20:54:18,515 - web_UI - ERROR - Traceback (most recent call last):
  File "C:\Users\16946\AppData\Local\Programs\Python\Python311\Lib\enum.py", line 688, in __call__
    def __call__(cls, value, names=None, *, module=None, qualname=None, type=None, start=1, boundary=None):
    
KeyboardInterrupt

2024-09-02 21:01:38,832 - web_UI - ERROR - Traceback (most recent call last):
  File "C:\Users\16946\Desktop\pythonProject\Auto_wed_current\Auto_UI\GUI_Template\GUI_Template_Perform\web_template_perform.py", line 90, in template_confirm
    self.cb.del_template()  # 取至web_perform_func
    ^^^^^^^^^^^^^^^^^^^^
AttributeError: 'web_combobox' object has no attribute 'del_template'

2024-09-02 21:02:31,855 - web_UI - ERROR - Traceback (most recent call last):
  File "C:\Users\16946\Desktop\pythonProject\Auto_wed_current\Auto_UI\GUI_Template\GIU_Template_File\append_file.py", line 12, in original_file
    thread_template_append(self.listWidget_original, condition).filedialog()
  File "C:\Users\16946\Desktop\pythonProject\Auto_wed_current\Auto_UI\GUI_Template\GUI_Template_Thread\thread_template_append.py", line 54, in filedialog
    thread_ds.append_data(filename_list, self.condition, text = self.text)
  File "_pydevd_bundle\\pydevd_cython_win32_311_64.pyx", line 1187, in _pydevd_bundle.pydevd_cython_win32_311_64.SafeCallWrapper.__call__
  File "_pydevd_bundle\\pydevd_cython_win32_311_64.pyx", line 627, in _pydevd_bundle.pydevd_cython_win32_311_64.PyDBFrame.trace_dispatch
  File "_pydevd_bundle\\pydevd_cython_win32_311_64.pyx", line 1103, in _pydevd_bundle.pydevd_cython_win32_311_64.PyDBFrame.trace_dispatch
  File "_pydevd_bundle\\pydevd_cython_win32_311_64.pyx", line 1096, in _pydevd_bundle.pydevd_cython_win32_311_64.PyDBFrame.trace_dispatch
  File "_pydevd_bundle\\pydevd_cython_win32_311_64.pyx", line 585, in _pydevd_bundle.pydevd_cython_win32_311_64.PyDBFrame.do_wait_suspend
  File "C:\Program Files\JetBrains\PyCharm 2024.2.0.1\plugins\python-ce\helpers\pydev\pydevd.py", line 1207, in do_wait_suspend
    self._do_wait_suspend(thread, frame, event, arg, suspend_type, from_this_thread)
  File "C:\Program Files\JetBrains\PyCharm 2024.2.0.1\plugins\python-ce\helpers\pydev\pydevd.py", line 1222, in _do_wait_suspend
    time.sleep(0.01)
KeyboardInterrupt

2024-09-02 21:05:51,111 - web_UI - ERROR - Traceback (most recent call last):
  File "C:\Users\16946\Desktop\pythonProject\Auto_wed_current\Auto_UI\GUI_Template\GIU_Template_File\append_file.py", line 12, in original_file
    thread_template_append(self.listWidget_original, condition).filedialog()
  File "C:\Users\16946\Desktop\pythonProject\Auto_wed_current\Auto_UI\GUI_Template\GUI_Template_Thread\thread_template_append.py", line 54, in filedialog
    # thread_ds.append_data(filename_list, self.condition, text = self.text)
    ^^^^^^^^^
  File "_pydevd_bundle\\pydevd_cython_win32_311_64.pyx", line 1187, in _pydevd_bundle.pydevd_cython_win32_311_64.SafeCallWrapper.__call__
  File "_pydevd_bundle\\pydevd_cython_win32_311_64.pyx", line 627, in _pydevd_bundle.pydevd_cython_win32_311_64.PyDBFrame.trace_dispatch
  File "_pydevd_bundle\\pydevd_cython_win32_311_64.pyx", line 1103, in _pydevd_bundle.pydevd_cython_win32_311_64.PyDBFrame.trace_dispatch
  File "_pydevd_bundle\\pydevd_cython_win32_311_64.pyx", line 1065, in _pydevd_bundle.pydevd_cython_win32_311_64.PyDBFrame.trace_dispatch
  File "_pydevd_bundle\\pydevd_cython_win32_311_64.pyx", line 585, in _pydevd_bundle.pydevd_cython_win32_311_64.PyDBFrame.do_wait_suspend
  File "C:\Program Files\JetBrains\PyCharm 2024.2.0.1\plugins\python-ce\helpers\pydev\pydevd.py", line 1207, in do_wait_suspend
    self._do_wait_suspend(thread, frame, event, arg, suspend_type, from_this_thread)
  File "C:\Program Files\JetBrains\PyCharm 2024.2.0.1\plugins\python-ce\helpers\pydev\pydevd.py", line 1222, in _do_wait_suspend
    time.sleep(0.01)
KeyboardInterrupt

2024-09-02 21:09:01,515 - web_UI - ERROR - Traceback (most recent call last):
  File "C:\Users\16946\Desktop\pythonProject\Auto_wed_current\Auto_UI\GUI_Template\GIU_Template_File\append_file.py", line 12, in original_file
    thread_template_append(self.listWidget_original, condition).filedialog()
  File "C:\Users\16946\Desktop\pythonProject\Auto_wed_current\Auto_UI\GUI_Template\GUI_Template_Thread\thread_template_append.py", line 51, in filedialog
    self.listWidget.addItems(filename)
TypeError: addItems(self, labels: Iterable[Optional[str]]): argument 1 has unexpected type 'str'

2024-09-02 21:09:54,426 - web_UI - ERROR - Traceback (most recent call last):
  File "C:\Users\16946\Desktop\pythonProject\Auto_wed_current\Auto_UI\GUI_Template\GIU_Template_File\append_file.py", line 12, in original_file
    thread_template_append(self.listWidget_original, condition).filedialog()
  File "C:\Users\16946\Desktop\pythonProject\Auto_wed_current\Auto_UI\GUI_Template\GUI_Template_Thread\thread_template_append.py", line 50, in filedialog
    elif filename not in listWidget_data:
         ^^^^^^^^
  File "_pydevd_bundle\\pydevd_cython_win32_311_64.pyx", line 1187, in _pydevd_bundle.pydevd_cython_win32_311_64.SafeCallWrapper.__call__
  File "_pydevd_bundle\\pydevd_cython_win32_311_64.pyx", line 627, in _pydevd_bundle.pydevd_cython_win32_311_64.PyDBFrame.trace_dispatch
  File "_pydevd_bundle\\pydevd_cython_win32_311_64.pyx", line 1103, in _pydevd_bundle.pydevd_cython_win32_311_64.PyDBFrame.trace_dispatch
  File "_pydevd_bundle\\pydevd_cython_win32_311_64.pyx", line 1065, in _pydevd_bundle.pydevd_cython_win32_311_64.PyDBFrame.trace_dispatch
  File "_pydevd_bundle\\pydevd_cython_win32_311_64.pyx", line 585, in _pydevd_bundle.pydevd_cython_win32_311_64.PyDBFrame.do_wait_suspend
  File "C:\Program Files\JetBrains\PyCharm 2024.2.0.1\plugins\python-ce\helpers\pydev\pydevd.py", line 1207, in do_wait_suspend
    self._do_wait_suspend(thread, frame, event, arg, suspend_type, from_this_thread)
  File "C:\Program Files\JetBrains\PyCharm 2024.2.0.1\plugins\python-ce\helpers\pydev\pydevd.py", line 1222, in _do_wait_suspend
    time.sleep(0.01)
KeyboardInterrupt

2024-09-02 21:09:57,164 - web_UI - ERROR - Traceback (most recent call last):
  File "C:\Users\16946\AppData\Local\Programs\Python\Python311\Lib\enum.py", line 688, in __call__
    def __call__(cls, value, names=None, *, module=None, qualname=None, type=None, start=1, boundary=None):
    
KeyboardInterrupt

2024-09-02 21:11:11,737 - web_UI - ERROR - Traceback (most recent call last):
  File "C:\Users\16946\Desktop\pythonProject\Auto_wed_current\Auto_UI\GUI_Template\GUI_Template_Perform\web_template_perform.py", line 90, in template_confirm
    self.cb.del_template()  # 取至web_perform_func
    ^^^^^^^^^^^^^^^^^^^^
AttributeError: 'web_combobox' object has no attribute 'del_template'

2024-09-02 22:04:29,223 - web_UI - ERROR - Traceback (most recent call last):
  File "C:\Users\16946\Desktop\pythonProject\Auto_wed_current\Auto_UI\web_qt_gui.py", line 46, in closeEvent
    driver.close()
  File "C:\Users\16946\Desktop\pythonProject\.venv\Lib\site-packages\selenium\webdriver\remote\webdriver.py", line 465, in close
    self.execute(Command.CLOSE)
  File "C:\Users\16946\Desktop\pythonProject\.venv\Lib\site-packages\selenium\webdriver\remote\webdriver.py", line 354, in execute
    self.error_handler.check_response(response)
  File "C:\Users\16946\Desktop\pythonProject\.venv\Lib\site-packages\selenium\webdriver\remote\errorhandler.py", line 229, in check_response
    raise exception_class(message, screen, stacktrace)
selenium.common.exceptions.WebDriverException: Message: disconnected: not connected to DevTools
  (failed to check if window was closed: disconnected: not connected to DevTools)
  (Session info: chrome=128.0.6613.114)
Stacktrace:
	GetHandleVerifier [0x00007FF70B2DB632+29090]
	(No symbol) [0x00007FF70B24E6E9]
	(No symbol) [0x00007FF70B10B1CA]
	(No symbol) [0x00007FF70B0F1296]
	(No symbol) [0x00007FF70B0F231F]
	(No symbol) [0x00007FF70B10B7E3]
	(No symbol) [0x00007FF70B0DF5ED]
	(No symbol) [0x00007FF70B195379]
	(No symbol) [0x00007FF70B1866B0]
	(No symbol) [0x00007FF70B1509B1]
	(No symbol) [0x00007FF70B151B11]
	GetHandleVerifier [0x00007FF70B5F883D+3294125]
	GetHandleVerifier [0x00007FF70B644423+3604371]
	GetHandleVerifier [0x00007FF70B63A2E7+3563095]
	GetHandleVerifier [0x00007FF70B396F16+797318]
	(No symbol) [0x00007FF70B25986F]
	(No symbol) [0x00007FF70B255454]
	(No symbol) [0x00007FF70B2555E0]
	(No symbol) [0x00007FF70B244A7F]
	BaseThreadInitThunk [0x00007FFF41E17374+20]
	RtlUserThreadStart [0x00007FFF43C3CC91+33]


2024-09-02 22:04:34,499 - web_UI - ERROR - Traceback (most recent call last):
  File "C:\Users\16946\AppData\Local\Programs\Python\Python311\Lib\enum.py", line 688, in __call__
    def __call__(cls, value, names=None, *, module=None, qualname=None, type=None, start=1, boundary=None):
    
KeyboardInterrupt

2024-09-02 22:09:19,047 - web_UI - ERROR - Traceback (most recent call last):
  File "C:\Users\16946\Desktop\pythonProject\Auto_wed_current\Auto_UI\GUI_Template\GIU_Template_File\delete_file.py", line 10, in original_file
    thread_template_delete(self.listWidget_original, condition=condition).listWidget()
TypeError: 'QListWidget' object is not callable

2024-09-02 22:10:48,849 - web_UI - ERROR - Traceback (most recent call last):
  File "C:\Users\16946\AppData\Local\Programs\Python\Python311\Lib\enum.py", line 688, in __call__
    def __call__(cls, value, names=None, *, module=None, qualname=None, type=None, start=1, boundary=None):
    
KeyboardInterrupt

2024-09-02 22:12:45,444 - web_UI - ERROR - Traceback (most recent call last):
  File "C:\Users\16946\Desktop\pythonProject\Auto_wed_current\Auto_UI\GUI_Template\GIU_Template_File\delete_file.py", line 10, in original_file
    thread_template_delete(self.listWidget_original, condition=condition).listWidget()
TypeError: 'QListWidget' object is not callable

2024-09-02 22:16:41,718 - web_UI - ERROR - Traceback (most recent call last):
  File "C:\Users\16946\Desktop\pythonProject\Auto_wed_current\Auto_UI\GUI_Template\GIU_Template_File\delete_file.py", line 10, in original_file
    thread_template_delete(self.listWidget_original, condition).listWidget()
TypeError: 'QListWidget' object is not callable

2024-09-02 22:16:44,489 - web_UI - ERROR - Traceback (most recent call last):
  File "C:\Users\16946\AppData\Local\Programs\Python\Python311\Lib\enum.py", line 688, in __call__
    def __call__(cls, value, names=None, *, module=None, qualname=None, type=None, start=1, boundary=None):
    
KeyboardInterrupt

2024-09-02 22:19:38,640 - web_UI - ERROR - Traceback (most recent call last):
  File "C:\Users\16946\Desktop\pythonProject\Auto_wed_current\Auto_UI\GUI_Template\GIU_Template_File\delete_file.py", line 12, in original_file
    thread_template.listWidget()
TypeError: 'QListWidget' object is not callable

2024-09-02 22:20:33,347 - web_UI - ERROR - Traceback (most recent call last):
  File "C:\Users\16946\Desktop\pythonProject\Auto_wed_current\Auto_UI\GUI_Template\GIU_Template_File\delete_file.py", line 12, in original_file
    thread_template.listWidget()
TypeError: 'QListWidget' object is not callable

2024-09-02 22:22:57,017 - web_UI - ERROR - Traceback (most recent call last):
  File "C:\Users\16946\Desktop\pythonProject\Auto_wed_current\Auto_UI\GUI_Template\GIU_Template_File\delete_file.py", line 10, in original_file
    thread_template_delete(self.listWidget_original, condition).listWidget()
TypeError: 'QListWidget' object is not callable

2024-09-02 22:31:35,542 - web_UI - ERROR - Traceback (most recent call last):
  File "C:\Users\16946\Desktop\pythonProject\Auto_wed_current\Auto_UI\GUI_Template\GIU_Template_File\delete_file.py", line 10, in original_file
    thread_template_delete(self.listWidget_original, condition).listWidget()
TypeError: 'QListWidget' object is not callable

2024-09-03 10:07:48,113 - web_UI - ERROR - Traceback (most recent call last):
  File "C:\Users\16946\Desktop\pythonProject\Auto_wed_current\Auto_execute\execute_while.py", line 65, in execute_function_original
    error_warning.error_account() # 【account】数据验证报错提示
    ^^^^^^^^^^^^^^^^^^^^^^^^^^^^^
  File "C:\Users\16946\Desktop\pythonProject\Auto_wed_current\Auto_base\error.py", line 117, in error_account
    raise error_reminder('error_account')
Auto_wed_current.Auto_base.error_reminder.error_reminder: [原始模板V1.0.xls]>[测试用例模板]>[第1行]报错，【account】数据只能填写为【account_01】

2024-09-03 10:08:16,215 - web_UI - ERROR - Traceback (most recent call last):
  File "C:\Users\16946\Desktop\pythonProject\Auto_wed_current\Auto_execute\execute_while.py", line 65, in execute_function_original
    error_warning.error_account() # 【account】数据验证报错提示
    ^^^^^^^^^^^^^^^^^^^^^^^^^^^^^
  File "C:\Users\16946\Desktop\pythonProject\Auto_wed_current\Auto_base\error.py", line 117, in error_account
    raise error_reminder('error_account')
Auto_wed_current.Auto_base.error_reminder.error_reminder: [原始模板V1.0.xls]>[测试用例模板]>[第1行]报错，【account】数据只能填写为【account_01】

2024-09-03 10:10:18,643 - web_UI - ERROR - Traceback (most recent call last):
  File "C:\Users\16946\Desktop\pythonProject\Auto_wed_current\Auto_UI\web_qt_gui.py", line 42, in closeEvent
    driver.close()
  File "C:\Users\16946\Desktop\pythonProject\.venv\Lib\site-packages\selenium\webdriver\remote\webdriver.py", line 465, in close
    self.execute(Command.CLOSE)
  File "C:\Users\16946\Desktop\pythonProject\.venv\Lib\site-packages\selenium\webdriver\remote\webdriver.py", line 354, in execute
    self.error_handler.check_response(response)
  File "C:\Users\16946\Desktop\pythonProject\.venv\Lib\site-packages\selenium\webdriver\remote\errorhandler.py", line 229, in check_response
    raise exception_class(message, screen, stacktrace)
selenium.common.exceptions.NoSuchWindowException: Message: no such window: target window already closed
from unknown error: web view not found
  (Session info: chrome=128.0.6613.114)
Stacktrace:
	GetHandleVerifier [0x00007FF7EEC8B632+29090]
	(No symbol) [0x00007FF7EEBFE6E9]
	(No symbol) [0x00007FF7EEABB1CA]
	(No symbol) [0x00007FF7EEA8FAF5]
	(No symbol) [0x00007FF7EEB3E2E7]
	(No symbol) [0x00007FF7EEB453D8]
	(No symbol) [0x00007FF7EEB366B0]
	(No symbol) [0x00007FF7EEB009B1]
	(No symbol) [0x00007FF7EEB01B11]
	GetHandleVerifier [0x00007FF7EEFA883D+3294125]
	GetHandleVerifier [0x00007FF7EEFF4423+3604371]
	GetHandleVerifier [0x00007FF7EEFEA2E7+3563095]
	GetHandleVerifier [0x00007FF7EED46F16+797318]
	(No symbol) [0x00007FF7EEC0986F]
	(No symbol) [0x00007FF7EEC05454]
	(No symbol) [0x00007FF7EEC055E0]
	(No symbol) [0x00007FF7EEBF4A7F]
	BaseThreadInitThunk [0x00007FFF41E17374+20]
	RtlUserThreadStart [0x00007FFF43C3CC91+33]


2024-09-03 10:33:00,372 - web_UI - ERROR - Traceback (most recent call last):
  File "C:\Users\16946\Desktop\pythonProject\Auto_wed_current\Auto_base\wait.py", line 24, in wait_element
    WebDriverWait(self.driver, self.wait_time).until(EC.presence_of_all_elements_located((By.XPATH, self.xpath)))
  File "C:\Users\16946\Desktop\pythonProject\.venv\Lib\site-packages\selenium\webdriver\support\wait.py", line 105, in until
    raise TimeoutException(message, screen, stacktrace)
selenium.common.exceptions.TimeoutException: Message: 


During handling of the above exception, another exception occurred:

Traceback (most recent call last):
  File "C:\Users\16946\Desktop\pythonProject\Auto_wed_current\Auto_execute\execute_while.py", line 104, in execute_function_original
    driver_wait(row, xpath, account, error, self.wait_time, excel_file=self.excel_file, excel_sheet=excel_sheet).wait_element()
  File "C:\Users\16946\Desktop\pythonProject\Auto_wed_current\Auto_base\wait.py", line 26, in wait_element
    raise error_reminder('wait_element')
Auto_wed_current.Auto_base.error_reminder.error_reminder: [原始模板V1.0.xls]>[测试用例模板]>[第5行]报错，页面等待超时

2024-09-03 10:33:37,864 - web_UI - ERROR - Traceback (most recent call last):
  File "C:\Users\16946\Desktop\pythonProject\Auto_wed_current\Auto_UI\web_qt_gui.py", line 42, in closeEvent
    driver.close()
  File "C:\Users\16946\Desktop\pythonProject\.venv\Lib\site-packages\selenium\webdriver\remote\webdriver.py", line 465, in close
    self.execute(Command.CLOSE)
  File "C:\Users\16946\Desktop\pythonProject\.venv\Lib\site-packages\selenium\webdriver\remote\webdriver.py", line 354, in execute
    self.error_handler.check_response(response)
  File "C:\Users\16946\Desktop\pythonProject\.venv\Lib\site-packages\selenium\webdriver\remote\errorhandler.py", line 229, in check_response
    raise exception_class(message, screen, stacktrace)
selenium.common.exceptions.WebDriverException: Message: disconnected: not connected to DevTools
  (failed to check if window was closed: disconnected: not connected to DevTools)
  (Session info: chrome=128.0.6613.114)
Stacktrace:
	GetHandleVerifier [0x00007FF7EEC8B632+29090]
	(No symbol) [0x00007FF7EEBFE6E9]
	(No symbol) [0x00007FF7EEABB1CA]
	(No symbol) [0x00007FF7EEAA1296]
	(No symbol) [0x00007FF7EEAA231F]
	(No symbol) [0x00007FF7EEABB7E3]
	(No symbol) [0x00007FF7EEA8F5ED]
	(No symbol) [0x00007FF7EEB45379]
	(No symbol) [0x00007FF7EEB366B0]
	(No symbol) [0x00007FF7EEB009B1]
	(No symbol) [0x00007FF7EEB01B11]
	GetHandleVerifier [0x00007FF7EEFA883D+3294125]
	GetHandleVerifier [0x00007FF7EEFF4423+3604371]
	GetHandleVerifier [0x00007FF7EEFEA2E7+3563095]
	GetHandleVerifier [0x00007FF7EED46F16+797318]
	(No symbol) [0x00007FF7EEC0986F]
	(No symbol) [0x00007FF7EEC05454]
	(No symbol) [0x00007FF7EEC055E0]
	(No symbol) [0x00007FF7EEBF4A7F]
	BaseThreadInitThunk [0x00007FFF41E17374+20]
	RtlUserThreadStart [0x00007FFF43C3CC91+33]


2024-09-03 15:24:27,683 - web_UI - ERROR - Traceback (most recent call last):
  File "C:\Users\16946\Desktop\pythonProject\Auto_wed_current\Auto_UI\GUI_Template\GUI_Template_Perform\web_template_perform.py", line 89, in template_close
    value = self.we.box_cancel("是否取消，取消不会保存当前值")
            ^^^^^^^^^^^^^^^^^^^^^^^^^^^^^^^^^^^^^^^^^^^^^^^^^^
  File "C:\Users\16946\Desktop\pythonProject\Auto_wed_current\Auto_UI\GUI_Error\web_error.py", line 77, in box_cancel
    buttonN.setText('取消')
    ^^^^^^^^^^^^^^^
AttributeError: 'NoneType' object has no attribute 'setText'

2024-09-03 15:25:52,798 - web_UI - ERROR - Traceback (most recent call last):
  File "C:\Users\16946\AppData\Local\Programs\Python\Python311\Lib\enum.py", line 688, in __call__
    def __call__(cls, value, names=None, *, module=None, qualname=None, type=None, start=1, boundary=None):
    
KeyboardInterrupt

2024-09-14 10:39:41,678 - web_UI - ERROR - Traceback (most recent call last):
  File "C:\Users\16946\AppData\Local\Programs\Python\Python311\Lib\enum.py", line 688, in __call__
    def __call__(cls, value, names=None, *, module=None, qualname=None, type=None, start=1, boundary=None):
    
KeyboardInterrupt

2024-09-14 11:19:30,871 - web_UI - ERROR - Traceback (most recent call last):
  File "C:\Users\16946\Desktop\pythonProject\Auto_wed_current\Auto_UI\GUI_Import_Export\web_import_export.py", line 13, in export_file
    self.we.export_csv()
  File "C:\Users\16946\Desktop\pythonProject\Auto_wed_current\Auto_UI\GUI_Import_Export\GUI_Im_Ex_Perform\web_export.py", line 10, in export_csv
    self.te.control_dict = self.control_dict # 来自web_combobox
                           ^^^^^^^^^^^^^^^^^
AttributeError: 'web_export' object has no attribute 'control_dict'

2024-09-20 00:10:08,800 - web_UI - ERROR - Traceback (most recent call last):
  File "C:\Users\16946\Desktop\pythonProject\Auto_wed_current\Auto_Post\GUI_Post_Perform\post_perform.py", line 41, in post_tableWidget_preview
    self.tableWidget_preview.setItem(0, col, QTableWidgetItem(item))
    ^^^^
  File "_pydevd_bundle\\pydevd_cython_win32_311_64.pyx", line 1187, in _pydevd_bundle.pydevd_cython_win32_311_64.SafeCallWrapper.__call__
  File "_pydevd_bundle\\pydevd_cython_win32_311_64.pyx", line 627, in _pydevd_bundle.pydevd_cython_win32_311_64.PyDBFrame.trace_dispatch
  File "_pydevd_bundle\\pydevd_cython_win32_311_64.pyx", line 1103, in _pydevd_bundle.pydevd_cython_win32_311_64.PyDBFrame.trace_dispatch
  File "_pydevd_bundle\\pydevd_cython_win32_311_64.pyx", line 1065, in _pydevd_bundle.pydevd_cython_win32_311_64.PyDBFrame.trace_dispatch
  File "_pydevd_bundle\\pydevd_cython_win32_311_64.pyx", line 585, in _pydevd_bundle.pydevd_cython_win32_311_64.PyDBFrame.do_wait_suspend
  File "C:\Program Files\JetBrains\PyCharm 2024.2.0.1\plugins\python-ce\helpers\pydev\pydevd.py", line 1207, in do_wait_suspend
    self._do_wait_suspend(thread, frame, event, arg, suspend_type, from_this_thread)
  File "C:\Program Files\JetBrains\PyCharm 2024.2.0.1\plugins\python-ce\helpers\pydev\pydevd.py", line 1222, in _do_wait_suspend
    time.sleep(0.01)
KeyboardInterrupt

2024-09-20 00:22:02,262 - web_UI - ERROR - Traceback (most recent call last):
  File "C:\Users\16946\AppData\Local\Programs\Python\Python311\Lib\enum.py", line 688, in __call__
    def __call__(cls, value, names=None, *, module=None, qualname=None, type=None, start=1, boundary=None):
    
KeyboardInterrupt

2024-09-20 00:23:06,924 - web_UI - ERROR - Traceback (most recent call last):
  File "C:\Users\16946\Desktop\pythonProject\Auto_wed_current\Auto_Post\GUI_Post_Perform\post_perform.py", line 38, in post_tableWidget_preview
    csv_reader = csv.reader(f)
                 ^^^
  File "_pydevd_bundle\\pydevd_cython_win32_311_64.pyx", line 1187, in _pydevd_bundle.pydevd_cython_win32_311_64.SafeCallWrapper.__call__
  File "_pydevd_bundle\\pydevd_cython_win32_311_64.pyx", line 627, in _pydevd_bundle.pydevd_cython_win32_311_64.PyDBFrame.trace_dispatch
  File "_pydevd_bundle\\pydevd_cython_win32_311_64.pyx", line 937, in _pydevd_bundle.pydevd_cython_win32_311_64.PyDBFrame.trace_dispatch
  File "_pydevd_bundle\\pydevd_cython_win32_311_64.pyx", line 928, in _pydevd_bundle.pydevd_cython_win32_311_64.PyDBFrame.trace_dispatch
  File "_pydevd_bundle\\pydevd_cython_win32_311_64.pyx", line 585, in _pydevd_bundle.pydevd_cython_win32_311_64.PyDBFrame.do_wait_suspend
  File "C:\Program Files\JetBrains\PyCharm 2024.2.0.1\plugins\python-ce\helpers\pydev\pydevd.py", line 1207, in do_wait_suspend
    self._do_wait_suspend(thread, frame, event, arg, suspend_type, from_this_thread)
  File "C:\Program Files\JetBrains\PyCharm 2024.2.0.1\plugins\python-ce\helpers\pydev\pydevd.py", line 1222, in _do_wait_suspend
    time.sleep(0.01)
KeyboardInterrupt

2024-09-20 00:25:52,910 - web_UI - ERROR - Traceback (most recent call last):
  File "C:\Users\16946\Desktop\pythonProject\Auto_wed_current\Auto_Post\GUI_Post_Perform\post_perform.py", line 39, in post_tableWidget_preview
    for row in csv_reader:
  File "<frozen codecs>", line 322, in decode
UnicodeDecodeError: 'utf-8' codec can't decode byte 0xb2 in position 0: invalid start byte

2024-09-20 00:27:48,446 - web_UI - ERROR - Traceback (most recent call last):
  File "C:\Users\16946\Desktop\pythonProject\Auto_wed_current\Auto_Post\GUI_Post_Perform\post_perform.py", line 39, in post_tableWidget_preview
    for row in csv_reader:
  File "<frozen codecs>", line 322, in decode
UnicodeDecodeError: 'utf-8' codec can't decode byte 0xb2 in position 0: invalid start byte

2024-09-20 08:43:34,954 - web_UI - ERROR - Traceback (most recent call last):
  File "C:\Users\16946\Desktop\pythonProject\Auto_wed_current\Auto_UI\web_qt_gui.py", line 42, in closeEvent
    driver.close()
  File "C:\Users\16946\Desktop\pythonProject\.venv\Lib\site-packages\selenium\webdriver\remote\webdriver.py", line 465, in close
    self.execute(Command.CLOSE)
  File "C:\Users\16946\Desktop\pythonProject\.venv\Lib\site-packages\selenium\webdriver\remote\webdriver.py", line 354, in execute
    self.error_handler.check_response(response)
  File "C:\Users\16946\Desktop\pythonProject\.venv\Lib\site-packages\selenium\webdriver\remote\errorhandler.py", line 229, in check_response
    raise exception_class(message, screen, stacktrace)
selenium.common.exceptions.WebDriverException: Message: disconnected: not connected to DevTools
  (failed to check if window was closed: disconnected: not connected to DevTools)
  (Session info: chrome=129.0.6668.58)
Stacktrace:
	GetHandleVerifier [0x00007FF7F7EAB632+29090]
	(No symbol) [0x00007FF7F7E1E6E9]
	(No symbol) [0x00007FF7F7CDB1CA]
	(No symbol) [0x00007FF7F7CC1296]
	(No symbol) [0x00007FF7F7CC231F]
	(No symbol) [0x00007FF7F7CDB7E3]
	(No symbol) [0x00007FF7F7CAF5ED]
	(No symbol) [0x00007FF7F7D65379]
	(No symbol) [0x00007FF7F7D566B0]
	(No symbol) [0x00007FF7F7D209B1]
	(No symbol) [0x00007FF7F7D21B11]
	GetHandleVerifier [0x00007FF7F81C883D+3294125]
	GetHandleVerifier [0x00007FF7F8214423+3604371]
	GetHandleVerifier [0x00007FF7F820A2E7+3563095]
	GetHandleVerifier [0x00007FF7F7F66F16+797318]
	(No symbol) [0x00007FF7F7E2986F]
	(No symbol) [0x00007FF7F7E25454]
	(No symbol) [0x00007FF7F7E255E0]
	(No symbol) [0x00007FF7F7E14A7F]
	BaseThreadInitThunk [0x00007FF90C997374+20]
	RtlUserThreadStart [0x00007FF90D3BCC91+33]


2024-09-20 09:03:57,476 - web_UI - ERROR - Traceback (most recent call last):
  File "C:\Users\16946\Desktop\pythonProject\Auto_wed_current\Auto_Post\GUI_Post_Thread\post_thread.py", line 23, in run
    self.pr.issue_resquest()
  File "C:\Users\16946\Desktop\pythonProject\Auto_wed_current\Auto_Post\GUI_Post_Request\post_request.py", line 14, in issue_resquest
LookupError: unknown encoding: gdk

2024-09-20 09:04:15,947 - web_UI - ERROR - Traceback (most recent call last):
  File "C:\Users\16946\Desktop\pythonProject\Auto_wed_current\Auto_UI\web_qt_gui.py", line 42, in closeEvent
    driver.close()
  File "C:\Users\16946\Desktop\pythonProject\.venv\Lib\site-packages\selenium\webdriver\remote\webdriver.py", line 465, in close
    self.execute(Command.CLOSE)
  File "C:\Users\16946\Desktop\pythonProject\.venv\Lib\site-packages\selenium\webdriver\remote\webdriver.py", line 354, in execute
    self.error_handler.check_response(response)
  File "C:\Users\16946\Desktop\pythonProject\.venv\Lib\site-packages\selenium\webdriver\remote\errorhandler.py", line 229, in check_response
    raise exception_class(message, screen, stacktrace)
selenium.common.exceptions.WebDriverException: Message: disconnected: not connected to DevTools
  (failed to check if window was closed: disconnected: not connected to DevTools)
  (Session info: chrome=129.0.6668.58)
Stacktrace:
	GetHandleVerifier [0x00007FF7F7EAB632+29090]
	(No symbol) [0x00007FF7F7E1E6E9]
	(No symbol) [0x00007FF7F7CDB1CA]
	(No symbol) [0x00007FF7F7CC1296]
	(No symbol) [0x00007FF7F7CC231F]
	(No symbol) [0x00007FF7F7CDB7E3]
	(No symbol) [0x00007FF7F7CAF5ED]
	(No symbol) [0x00007FF7F7D65379]
	(No symbol) [0x00007FF7F7D566B0]
	(No symbol) [0x00007FF7F7D209B1]
	(No symbol) [0x00007FF7F7D21B11]
	GetHandleVerifier [0x00007FF7F81C883D+3294125]
	GetHandleVerifier [0x00007FF7F8214423+3604371]
	GetHandleVerifier [0x00007FF7F820A2E7+3563095]
	GetHandleVerifier [0x00007FF7F7F66F16+797318]
	(No symbol) [0x00007FF7F7E2986F]
	(No symbol) [0x00007FF7F7E25454]
	(No symbol) [0x00007FF7F7E255E0]
	(No symbol) [0x00007FF7F7E14A7F]
	BaseThreadInitThunk [0x00007FF90C997374+20]
	RtlUserThreadStart [0x00007FF90D3BCC91+33]


