2024-11-01 22:33:04,908 - web_UI - ERROR - Traceback (most recent call last):
  File "C:\Users\16946\Desktop\文件\文件\siwu\Auto_wed_current\Auto_UI\web_qt_gui.py", line 52, in closeEvent
    driver = driver_class().driver_Chrome('account_01')
             ^^^^^^^^^^^^^^^^^^^^^^^^^^^^^^^^^^^^^^^^^^
  File "C:\Users\16946\Desktop\文件\文件\siwu\Auto_wed_current\Auto_driver\driver_class.py", line 26, in driver_Chrome
    return self.driver_01
           ^^^^^^^^^^^^^^
AttributeError: 'driver_class' object has no attribute 'driver_01'

2024-11-01 22:33:18,893 - web_UI - ERROR - Traceback (most recent call last):
  File "C:\Users\16946\Desktop\文件\文件\siwu\Auto_wed_current\Auto_UI\web_qt_gui.py", line 52, in closeEvent
    driver = driver_class().driver_Chrome('account_01')
             ^^^^^^^^^^^^^^^^^^^^^^^^^^^^^^^^^^^^^^^^^^
  File "C:\Users\16946\Desktop\文件\文件\siwu\Auto_wed_current\Auto_driver\driver_class.py", line 26, in driver_Chrome
    return self.driver_01
           ^^^^^^^^^^^^^^
AttributeError: 'driver_class' object has no attribute 'driver_01'

2024-11-01 22:33:40,075 - web_UI - ERROR - Traceback (most recent call last):
  File "C:\Users\16946\Desktop\文件\文件\siwu\Auto_wed_current\Auto_UI\web_qt_gui.py", line 52, in closeEvent
    driver = driver_class().driver_Chrome('account_01')
             ^^^^^^^^^^^^^^^^^^^^^^^^^^^^^^^^^^^^^^^^^^
  File "C:\Users\16946\Desktop\文件\文件\siwu\Auto_wed_current\Auto_driver\driver_class.py", line 26, in driver_Chrome
    return self.driver_01
           ^^^^^^^^^^^^^^
AttributeError: 'driver_class' object has no attribute 'driver_01'

2024-11-01 22:34:08,883 - web_UI - ERROR - Traceback (most recent call last):
  File "C:\Users\16946\Desktop\文件\文件\siwu\Auto_wed_current\Auto_UI\web_qt_gui.py", line 52, in closeEvent
    driver = driver_class().driver_Chrome('account_01')
             ^^^^^^^^^^^^^^^^^^^^^^^^^^^^^^^^^^^^^^^^^^
  File "C:\Users\16946\Desktop\文件\文件\siwu\Auto_wed_current\Auto_driver\driver_class.py", line 26, in driver_Chrome
    return self.driver_01
           ^^^^^^^^^^^^^^
AttributeError: 'driver_class' object has no attribute 'driver_01'

2024-11-01 22:42:35,838 - web_UI - ERROR - Traceback (most recent call last):
  File "C:\Users\16946\Desktop\文件\文件\siwu\Auto_wed_current\Auto_UI\web_qt_gui.py", line 52, in closeEvent
    driver = driver_class().driver_Chrome('account_01')
             ^^^^^^^^^^^^^^^^^^^^^^^^^^^^^^^^^^^^^^^^^^
  File "C:\Users\16946\Desktop\文件\文件\siwu\Auto_wed_current\Auto_driver\driver_class.py", line 26, in driver_Chrome
    return self.driver_01
           ^^^^^^^^^^^^^^
AttributeError: 'driver_class' object has no attribute 'driver_01'

2024-11-01 23:19:36,124 - web_UI - ERROR - Traceback (most recent call last):
  File "C:\Users\16946\Desktop\文件\文件\siwu\Auto_wed_current\Auto_Post\GUI_Post_ComboBox\post_combobox.py", line 134, in <lambda>
    control_groove_locals[i + 'test'] = lambda: self.preview_line(self.control_dict[line]['box_file'].currentText())
                                                ^^^^^^^^^^^^^^^^^^^^^^^^^^^^^^^^^^^^^^^^^^^^^^^^^^^^^^^^^^^^^^^^^^^^
  File "C:\Users\16946\Desktop\文件\文件\siwu\Auto_wed_current\Auto_Post\GUI_Post_ComboBox\post_combobox.py", line 275, in preview_line
    self.tableWidget_preview.cellEntered.connect(self.show_tooltip)
                                                 ^^^^^^^^^^^^^^^^^
AttributeError: 'post_combobox' object has no attribute 'show_tooltip'

2024-11-01 23:35:11,499 - web_UI - ERROR - Traceback (most recent call last):
  File "C:\Users\16946\Desktop\文件\文件\siwu\Auto_wed_current\Auto_Post\GUI_Post_ComboBox\post_combobox.py", line 282, in show_tooltip
    self.tableWidget_preview.cellRect(row, column).topLeft())
    ^^^^^^^^^^^^^^^^^^^^^^^^^^^^^^^^^
AttributeError: 'QTableWidget' object has no attribute 'cellRect'

2024-11-01 23:35:12,557 - web_UI - ERROR - Traceback (most recent call last):
  File "C:\Users\16946\Desktop\文件\文件\siwu\Auto_wed_current\Auto_Post\GUI_Post_ComboBox\post_combobox.py", line 282, in show_tooltip
    self.tableWidget_preview.cellRect(row, column).topLeft())
    ^^^^^^^^^^^^^^^^^^^^^^^^^^^^^^^^^
AttributeError: 'QTableWidget' object has no attribute 'cellRect'

2024-11-01 23:35:13,070 - web_UI - ERROR - Traceback (most recent call last):
  File "C:\Users\16946\Desktop\文件\文件\siwu\Auto_wed_current\Auto_Post\GUI_Post_ComboBox\post_combobox.py", line 282, in show_tooltip
    self.tableWidget_preview.cellRect(row, column).topLeft())
    ^^^^^^^^^^^^^^^^^^^^^^^^^^^^^^^^^
AttributeError: 'QTableWidget' object has no attribute 'cellRect'

2024-11-01 23:35:13,529 - web_UI - ERROR - Traceback (most recent call last):
  File "C:\Users\16946\Desktop\文件\文件\siwu\Auto_wed_current\Auto_Post\GUI_Post_ComboBox\post_combobox.py", line 282, in show_tooltip
    self.tableWidget_preview.cellRect(row, column).topLeft())
    ^^^^^^^^^^^^^^^^^^^^^^^^^^^^^^^^^
AttributeError: 'QTableWidget' object has no attribute 'cellRect'

2024-11-01 23:35:13,947 - web_UI - ERROR - Traceback (most recent call last):
  File "C:\Users\16946\Desktop\文件\文件\siwu\Auto_wed_current\Auto_Post\GUI_Post_ComboBox\post_combobox.py", line 282, in show_tooltip
    self.tableWidget_preview.cellRect(row, column).topLeft())
    ^^^^^^^^^^^^^^^^^^^^^^^^^^^^^^^^^
AttributeError: 'QTableWidget' object has no attribute 'cellRect'

2024-11-01 23:35:14,325 - web_UI - ERROR - Traceback (most recent call last):
  File "C:\Users\16946\Desktop\文件\文件\siwu\Auto_wed_current\Auto_Post\GUI_Post_ComboBox\post_combobox.py", line 282, in show_tooltip
    self.tableWidget_preview.cellRect(row, column).topLeft())
    ^^^^^^^^^^^^^^^^^^^^^^^^^^^^^^^^^
AttributeError: 'QTableWidget' object has no attribute 'cellRect'

2024-11-02 00:41:38,417 - web_UI - ERROR - Traceback (most recent call last):
  File "C:\Users\16946\Desktop\文件\文件\siwu\Auto_wed_current\Auto_UI\web_qt_gui.py", line 52, in closeEvent
    driver = driver_class().driver_Chrome('account_01')
             ^^^^^^^^^^^^^^^^^^^^^^^^^^^^^^^^^^^^^^^^^^
  File "C:\Users\16946\Desktop\文件\文件\siwu\Auto_wed_current\Auto_driver\driver_class.py", line 26, in driver_Chrome
    return self.driver_01
           ^^^^^^^^^^^^^^
AttributeError: 'driver_class' object has no attribute 'driver_01'

2024-11-02 00:42:03,896 - web_UI - ERROR - Traceback (most recent call last):
  File "C:\Users\16946\Desktop\文件\文件\siwu\Auto_wed_current\Auto_UI\web_qt_gui.py", line 52, in closeEvent
    driver = driver_class().driver_Chrome('account_01')
             ^^^^^^^^^^^^^^^^^^^^^^^^^^^^^^^^^^^^^^^^^^
  File "C:\Users\16946\Desktop\文件\文件\siwu\Auto_wed_current\Auto_driver\driver_class.py", line 26, in driver_Chrome
    return self.driver_01
           ^^^^^^^^^^^^^^
AttributeError: 'driver_class' object has no attribute 'driver_01'

2024-11-02 00:44:32,192 - web_UI - ERROR - Traceback (most recent call last):
  File "C:\Users\16946\Desktop\文件\文件\siwu\Auto_wed_current\Auto_Post\GUI_Post_ComboBox\post_combobox.py", line 280, in show_tooltip
    QToolTip.showText(self.tableWidget_preview.mapToGlobal(self.tableWidget_preview.visualRect(item).topLeft()),
                                                           ^^^^^^^^^^^^^^^^^^^^^^^^^^^^^^^^^^^^^^^^^
TypeError: visualRect(self, index: QModelIndex): argument 1 has unexpected type 'QTableWidgetItem'

2024-11-02 00:46:03,373 - web_UI - ERROR - Traceback (most recent call last):
  File "C:\Users\16946\Desktop\文件\文件\siwu\Auto_wed_current\Auto_Post\GUI_Post_ComboBox\post_combobox.py", line 280, in show_tooltip
    QToolTip.showText("你好")
TypeError: showText(pos: QPoint, text: str, widget: typing.Optional[QWidget] = None, rect: QRect = {}, msecShowTime: int = -1): argument 1 has unexpected type 'str'

2024-11-02 00:50:13,093 - web_UI - ERROR - Traceback (most recent call last):
  File "C:\Users\16946\Desktop\文件\文件\siwu\Auto_wed_current\Auto_Post\GUI_Post_ComboBox\post_combobox.py", line 280, in show_tooltip
    QToolTip.showText(self.tableWidget_preview.mapToGlobal(self.tableWidget_preview.visualRect(item).topLeft()), item.text())
                                                           ^^^^^^^^^^^^^^^^^^^^^^^^^^^^^^^^^^^^^^^^^
TypeError: visualRect(self, index: QModelIndex): argument 1 has unexpected type 'QTableWidgetItem'

2024-11-02 10:23:41,706 - web_UI - ERROR - Traceback (most recent call last):
  File "C:\Users\16946\Desktop\文件\文件\siwu\Auto_wed_current\Auto_UI\web_qt_gui.py", line 52, in closeEvent
    driver = driver_class().driver_Chrome('account_01')
             ^^^^^^^^^^^^^^^^^^^^^^^^^^^^^^^^^^^^^^^^^^
  File "C:\Users\16946\Desktop\文件\文件\siwu\Auto_wed_current\Auto_driver\driver_class.py", line 26, in driver_Chrome
    return self.driver_01
           ^^^^^^^^^^^^^^
AttributeError: 'driver_class' object has no attribute 'driver_01'

2024-11-02 11:24:53,375 - web_UI - ERROR - Traceback (most recent call last):
  File "C:\Users\16946\Desktop\siwu\Auto_wed_current\Auto_UI\web_qt_gui.py", line 52, in closeEvent
    driver = driver_class().driver_Chrome('account_01')
             ^^^^^^^^^^^^^^^^^^^^^^^^^^^^^^^^^^^^^^^^^^
  File "C:\Users\16946\Desktop\siwu\Auto_wed_current\Auto_driver\driver_class.py", line 26, in driver_Chrome
    return self.driver_01
           ^^^^^^^^^^^^^^
AttributeError: 'driver_class' object has no attribute 'driver_01'

2024-11-02 11:34:21,945 - web_UI - ERROR - Traceback (most recent call last):
  File "C:\Users\16946\Desktop\siwu\Auto_wed_current\Auto_UI\web_qt_gui.py", line 53, in closeEvent
    driver.close()
  File "C:\Users\16946\Desktop\siwu\.venv\Lib\site-packages\selenium\webdriver\remote\webdriver.py", line 491, in close
    self.execute(Command.CLOSE)
  File "C:\Users\16946\Desktop\siwu\.venv\Lib\site-packages\selenium\webdriver\remote\webdriver.py", line 380, in execute
    self.error_handler.check_response(response)
  File "C:\Users\16946\Desktop\siwu\.venv\Lib\site-packages\selenium\webdriver\remote\errorhandler.py", line 229, in check_response
    raise exception_class(message, screen, stacktrace)
selenium.common.exceptions.WebDriverException: Message: disconnected: not connected to DevTools
  (failed to check if window was closed: disconnected: not connected to DevTools)
  (Session info: chrome=130.0.6723.92)
Stacktrace:
	GetHandleVerifier [0x00007FF78D553AF5+28005]
	(No symbol) [0x00007FF78D4B83F0]
	(No symbol) [0x00007FF78D35580A]
	(No symbol) [0x00007FF78D340B06]
	(No symbol) [0x00007FF78D341FCF]
	(No symbol) [0x00007FF78D355E23]
	(No symbol) [0x00007FF78D32F55D]
	(No symbol) [0x00007FF78D3D9CE9]
	(No symbol) [0x00007FF78D3CBA00]
	(No symbol) [0x00007FF78D3975C8]
	(No symbol) [0x00007FF78D398731]
	GetHandleVerifier [0x00007FF78D84646D+3118813]
	GetHandleVerifier [0x00007FF78D896CC0+3448624]
	GetHandleVerifier [0x00007FF78D88CF3D+3408301]
	GetHandleVerifier [0x00007FF78D61A44B+841403]
	(No symbol) [0x00007FF78D4C344F]
	(No symbol) [0x00007FF78D4BF4C4]
	(No symbol) [0x00007FF78D4BF65D]
	(No symbol) [0x00007FF78D4AEBB9]
	BaseThreadInitThunk [0x00007FFAE4FC257D+29]
	RtlUserThreadStart [0x00007FFAE71AAF08+40]


2024-11-02 17:09:17,196 - web_UI - ERROR - Traceback (most recent call last):
  File "C:\Users\16946\Desktop\siwu\.venv\Lib\site-packages\urllib3\connection.py", line 199, in _new_conn
    sock = connection.create_connection(
           ^^^^^^^^^^^^^^^^^^^^^^^^^^^^^
  File "C:\Users\16946\Desktop\siwu\.venv\Lib\site-packages\urllib3\util\connection.py", line 85, in create_connection
    raise err
  File "C:\Users\16946\Desktop\siwu\.venv\Lib\site-packages\urllib3\util\connection.py", line 73, in create_connection
    sock.connect(sa)
ConnectionRefusedError: [WinError 10061] 由于目标计算机积极拒绝，无法连接。

The above exception was the direct cause of the following exception:

Traceback (most recent call last):
  File "C:\Users\16946\Desktop\siwu\.venv\Lib\site-packages\urllib3\connectionpool.py", line 789, in urlopen
    response = self._make_request(
               ^^^^^^^^^^^^^^^^^^^
  File "C:\Users\16946\Desktop\siwu\.venv\Lib\site-packages\urllib3\connectionpool.py", line 490, in _make_request
    raise new_e
  File "C:\Users\16946\Desktop\siwu\.venv\Lib\site-packages\urllib3\connectionpool.py", line 466, in _make_request
    self._validate_conn(conn)
  File "C:\Users\16946\Desktop\siwu\.venv\Lib\site-packages\urllib3\connectionpool.py", line 1095, in _validate_conn
    conn.connect()
  File "C:\Users\16946\Desktop\siwu\.venv\Lib\site-packages\urllib3\connection.py", line 693, in connect
    self.sock = sock = self._new_conn()
                       ^^^^^^^^^^^^^^^^
  File "C:\Users\16946\Desktop\siwu\.venv\Lib\site-packages\urllib3\connection.py", line 214, in _new_conn
    raise NewConnectionError(
urllib3.exceptions.NewConnectionError: <urllib3.connection.HTTPSConnection object at 0x000001EE324C1010>: Failed to establish a new connection: [WinError 10061] 由于目标计算机积极拒绝，无法连接。

The above exception was the direct cause of the following exception:

Traceback (most recent call last):
  File "C:\Users\16946\Desktop\siwu\.venv\Lib\site-packages\requests\adapters.py", line 667, in send
    resp = conn.urlopen(
           ^^^^^^^^^^^^^
  File "C:\Users\16946\Desktop\siwu\.venv\Lib\site-packages\urllib3\connectionpool.py", line 843, in urlopen
    retries = retries.increment(
              ^^^^^^^^^^^^^^^^^^
  File "C:\Users\16946\Desktop\siwu\.venv\Lib\site-packages\urllib3\util\retry.py", line 519, in increment
    raise MaxRetryError(_pool, url, reason) from reason  # type: ignore[arg-type]
    ^^^^^^^^^^^^^^^^^^^^^^^^^^^^^^^^^^^^^^^^^^^^^^^^^^^
urllib3.exceptions.MaxRetryError: HTTPSConnectionPool(host='api.oioweb.cn', port=443): Max retries exceeded with url: /api/common/OneDayEnglish (Caused by NewConnectionError('<urllib3.connection.HTTPSConnection object at 0x000001EE324C1010>: Failed to establish a new connection: [WinError 10061] 由于目标计算机积极拒绝，无法连接。'))

During handling of the above exception, another exception occurred:

Traceback (most recent call last):
  File "C:\Users\16946\Desktop\siwu\Auto_wed_current\Auto_Post\GUI_Post_Thread\post_thread.py", line 24, in run
    self.pr.issue_resquest(self.post_combobox)
  File "C:\Users\16946\Desktop\siwu\Auto_wed_current\Auto_Post\GUI_Post_Request\post_request.py", line 16, in issue_resquest
    self.mode_request(row)
  File "C:\Users\16946\Desktop\siwu\Auto_wed_current\Auto_Post\GUI_Post_Request\post_request.py", line 21, in mode_request
    r = requests.get(request[3])
        ^^^^^^^^^^^^^^^^^^^^^^^^
  File "C:\Users\16946\Desktop\siwu\.venv\Lib\site-packages\requests\api.py", line 73, in get
    return request("get", url, params=params, **kwargs)
           ^^^^^^^^^^^^^^^^^^^^^^^^^^^^^^^^^^^^^^^^^^^^
  File "C:\Users\16946\Desktop\siwu\.venv\Lib\site-packages\requests\api.py", line 59, in request
    return session.request(method=method, url=url, **kwargs)
           ^^^^^^^^^^^^^^^^^^^^^^^^^^^^^^^^^^^^^^^^^^^^^^^^^
  File "C:\Users\16946\Desktop\siwu\.venv\Lib\site-packages\requests\sessions.py", line 589, in request
    resp = self.send(prep, **send_kwargs)
           ^^^^^^^^^^^^^^^^^^^^^^^^^^^^^^
  File "C:\Users\16946\Desktop\siwu\.venv\Lib\site-packages\requests\sessions.py", line 703, in send
    r = adapter.send(request, **kwargs)
        ^^^^^^^^^^^^^^^^^^^^^^^^^^^^^^^
  File "C:\Users\16946\Desktop\siwu\.venv\Lib\site-packages\requests\adapters.py", line 700, in send
    raise ConnectionError(e, request=request)
requests.exceptions.ConnectionError: HTTPSConnectionPool(host='api.oioweb.cn', port=443): Max retries exceeded with url: /api/common/OneDayEnglish (Caused by NewConnectionError('<urllib3.connection.HTTPSConnection object at 0x000001EE324C1010>: Failed to establish a new connection: [WinError 10061] 由于目标计算机积极拒绝，无法连接。'))

2024-11-02 18:11:23,837 - web_UI - ERROR - Traceback (most recent call last):
  File "C:\Users\16946\Desktop\siwu\Auto_wed_current\Auto_Post\GUI_Post_ComboBox\post_combobox.py", line 44, in data_clear
    bu_del['bu_del'].click()
    ~~~~~~^^^^^^^^^^
TypeError: 'int' object is not subscriptable

2024-11-02 18:13:18,276 - web_UI - ERROR - Traceback (most recent call last):
  File "C:\Users\16946\Desktop\siwu\Auto_wed_current\Auto_Post\GUI_Post_ComboBox\post_combobox.py", line 44, in data_clear
    bu_del['bu_del'].click()
    ^^^^^^
  File "_pydevd_bundle\\pydevd_cython_win32_311_64.pyx", line 1187, in _pydevd_bundle.pydevd_cython_win32_311_64.SafeCallWrapper.__call__
  File "_pydevd_bundle\\pydevd_cython_win32_311_64.pyx", line 627, in _pydevd_bundle.pydevd_cython_win32_311_64.PyDBFrame.trace_dispatch
  File "_pydevd_bundle\\pydevd_cython_win32_311_64.pyx", line 1103, in _pydevd_bundle.pydevd_cython_win32_311_64.PyDBFrame.trace_dispatch
  File "_pydevd_bundle\\pydevd_cython_win32_311_64.pyx", line 1065, in _pydevd_bundle.pydevd_cython_win32_311_64.PyDBFrame.trace_dispatch
  File "_pydevd_bundle\\pydevd_cython_win32_311_64.pyx", line 585, in _pydevd_bundle.pydevd_cython_win32_311_64.PyDBFrame.do_wait_suspend
  File "C:\Program Files\JetBrains\PyCharm 2024.2.1\plugins\python-ce\helpers\pydev\pydevd.py", line 1207, in do_wait_suspend
    self._do_wait_suspend(thread, frame, event, arg, suspend_type, from_this_thread)
  File "C:\Program Files\JetBrains\PyCharm 2024.2.1\plugins\python-ce\helpers\pydev\pydevd.py", line 1222, in _do_wait_suspend
    time.sleep(0.01)
KeyboardInterrupt

2024-11-02 18:13:48,754 - web_UI - ERROR - Traceback (most recent call last):
  File "C:\Users\16946\Desktop\siwu\Auto_wed_current\Auto_Post\GUI_Post_ComboBox\post_combobox.py", line 43, in data_clear
    for bu_del in self.control_dict:
RuntimeError: dictionary changed size during iteration

2024-11-02 18:17:31,646 - web_UI - ERROR - Traceback (most recent call last):
  File "C:\Users\16946\Desktop\siwu\Auto_wed_current\Auto_Post\GUI_Post_ComboBox\post_combobox.py", line 45, in data_clear
    self.control_dict[1]['bu_del'].click()
    ^^^^
  File "_pydevd_bundle\\pydevd_cython_win32_311_64.pyx", line 1187, in _pydevd_bundle.pydevd_cython_win32_311_64.SafeCallWrapper.__call__
  File "_pydevd_bundle\\pydevd_cython_win32_311_64.pyx", line 627, in _pydevd_bundle.pydevd_cython_win32_311_64.PyDBFrame.trace_dispatch
  File "_pydevd_bundle\\pydevd_cython_win32_311_64.pyx", line 1103, in _pydevd_bundle.pydevd_cython_win32_311_64.PyDBFrame.trace_dispatch
  File "_pydevd_bundle\\pydevd_cython_win32_311_64.pyx", line 1065, in _pydevd_bundle.pydevd_cython_win32_311_64.PyDBFrame.trace_dispatch
  File "_pydevd_bundle\\pydevd_cython_win32_311_64.pyx", line 585, in _pydevd_bundle.pydevd_cython_win32_311_64.PyDBFrame.do_wait_suspend
  File "C:\Program Files\JetBrains\PyCharm 2024.2.1\plugins\python-ce\helpers\pydev\pydevd.py", line 1207, in do_wait_suspend
    self._do_wait_suspend(thread, frame, event, arg, suspend_type, from_this_thread)
  File "C:\Program Files\JetBrains\PyCharm 2024.2.1\plugins\python-ce\helpers\pydev\pydevd.py", line 1222, in _do_wait_suspend
    time.sleep(0.01)
KeyboardInterrupt

2024-11-02 18:18:00,505 - web_UI - ERROR - Traceback (most recent call last):
  File "C:\Users\16946\Desktop\siwu\Auto_wed_current\Auto_Post\GUI_Post_ComboBox\post_combobox.py", line 45, in data_clear
    self.control_dict[2]['bu_del'].click()
    ~~~~~~~~~~~~~~~~~^^^
KeyError: 2

During handling of the above exception, another exception occurred:

Traceback (most recent call last):
  File "C:\Users\16946\Desktop\siwu\Auto_wed_current\Auto_Post\GUI_Post_ComboBox\post_combobox.py", line 47, in data_clear
    self.control_dict[2]['bu_del'].click()
    ~~~~~~~~~~~~~~~~~^^^
KeyError: 2

2024-11-02 18:18:03,608 - web_UI - ERROR - Traceback (most recent call last):
  File "C:\Users\16946\Desktop\siwu\Auto_wed_current\Auto_Post\GUI_Post_ComboBox\post_combobox.py", line 45, in data_clear
    self.control_dict[2]['bu_del'].click()
    ~~~~~~~~~~~~~~~~~^^^
KeyError: 2

During handling of the above exception, another exception occurred:

Traceback (most recent call last):
  File "C:\Users\16946\Desktop\siwu\Auto_wed_current\Auto_Post\GUI_Post_ComboBox\post_combobox.py", line 47, in data_clear
    self.control_dict[2]['bu_del'].click()
    ~~~~~~~~~~~~~~~~~^^^
KeyError: 2

2024-11-02 18:18:11,180 - web_UI - ERROR - Traceback (most recent call last):
  File "C:\Users\16946\Desktop\siwu\Auto_wed_current\Auto_Post\GUI_Post_ComboBox\post_combobox.py", line 45, in data_clear
    self.control_dict[2]['bu_del'].click()
    ~~~~~~~~~~~~~~~~~^^^
KeyError: 2

During handling of the above exception, another exception occurred:

Traceback (most recent call last):
  File "C:\Users\16946\Desktop\siwu\Auto_wed_current\Auto_Post\GUI_Post_ComboBox\post_combobox.py", line 47, in data_clear
    self.control_dict[2]['bu_del'].click()
    ~~~~~~~~~~~~~~~~~^^^
KeyError: 2

2024-11-02 18:18:17,575 - web_UI - ERROR - Traceback (most recent call last):
  File "C:\Users\16946\Desktop\siwu\Auto_wed_current\Auto_Post\GUI_Post_ComboBox\post_combobox.py", line 45, in data_clear
    self.control_dict[2]['bu_del'].click()
    ~~~~~~~~~~~~~~~~~^^^
KeyError: 2

During handling of the above exception, another exception occurred:

Traceback (most recent call last):
  File "C:\Users\16946\Desktop\siwu\Auto_wed_current\Auto_Post\GUI_Post_ComboBox\post_combobox.py", line 47, in data_clear
    self.control_dict[2]['bu_del'].click()
    ~~~~~~~~~~~~~~~~~^^^
KeyError: 2

2024-11-02 18:29:10,096 - web_UI - ERROR - Traceback (most recent call last):
  File "C:\Users\16946\Desktop\siwu\Auto_wed_current\Auto_Post\GUI_Post_Template\post_template.py", line 36, in closeEvent
    self.pushButton_data_clear.click()
    ^^^^^^^^^^^^^^^^^^^^^^^^^^
AttributeError: 'post_template' object has no attribute 'pushButton_data_clear'

2024-11-02 18:30:20,267 - web_UI - ERROR - Traceback (most recent call last):
  File "C:\Users\16946\Desktop\siwu\Auto_wed_current\Auto_Post\GUI_Post_Template\post_template.py", line 38, in closeEvent
    self.pushButton_data_clear.click()
    ^^^^^^^^^^^^^^^^^^^^^^^^^^
AttributeError: 'post_template' object has no attribute 'pushButton_data_clear'

2024-11-02 18:33:36,399 - web_UI - ERROR - Traceback (most recent call last):
  File "C:\Users\16946\Desktop\siwu\Auto_wed_current\Auto_UI\GUI_Perform\web_perform_func.py", line 139, in open_interface
    self.pw = post_window()  # 打开接口窗口
              ^^^^^^^^^^^^^
  File "C:\Users\16946\Desktop\siwu\Auto_wed_current\Auto_Post\post_window.py", line 22, in __init__
    self.tp = post_template()  # 编辑模板
              ^^^^^^^^^^^^^^^
  File "C:\Users\16946\Desktop\siwu\Auto_wed_current\Auto_Post\GUI_Post_Template\post_template.py", line 21, in __init__
    self.setupUi(self)
  File "C:\Users\16946\Desktop\siwu\Auto_wed_current\Auto_Post\GUI_Post_Untitled\untitled_post_template.py", line 14, in setupUi
    Form_Template.setObjectName("Form_Template")
RuntimeError: super-class __init__() of type post_template was never called

2024-11-02 18:33:37,827 - web_UI - ERROR - Traceback (most recent call last):
  File "C:\Users\16946\Desktop\siwu\Auto_wed_current\Auto_UI\GUI_Perform\web_perform_func.py", line 139, in open_interface
    self.pw = post_window()  # 打开接口窗口
              ^^^^^^^^^^^^^
  File "C:\Users\16946\Desktop\siwu\Auto_wed_current\Auto_Post\post_window.py", line 22, in __init__
    self.tp = post_template()  # 编辑模板
              ^^^^^^^^^^^^^^^
  File "C:\Users\16946\Desktop\siwu\Auto_wed_current\Auto_Post\GUI_Post_Template\post_template.py", line 21, in __init__
    self.setupUi(self)
  File "C:\Users\16946\Desktop\siwu\Auto_wed_current\Auto_Post\GUI_Post_Untitled\untitled_post_template.py", line 14, in setupUi
    Form_Template.setObjectName("Form_Template")
RuntimeError: super-class __init__() of type post_template was never called

2024-11-02 18:33:40,158 - web_UI - ERROR - Traceback (most recent call last):
  File "C:\Users\16946\Desktop\siwu\Auto_wed_current\Auto_UI\GUI_Perform\web_perform_func.py", line 139, in open_interface
    self.pw = post_window()  # 打开接口窗口
              ^^^^^^^^^^^^^
  File "C:\Users\16946\Desktop\siwu\Auto_wed_current\Auto_Post\post_window.py", line 22, in __init__
    self.tp = post_template()  # 编辑模板
              ^^^^^^^^^^^^^^^
  File "C:\Users\16946\Desktop\siwu\Auto_wed_current\Auto_Post\GUI_Post_Template\post_template.py", line 21, in __init__
    self.setupUi(self)
  File "C:\Users\16946\Desktop\siwu\Auto_wed_current\Auto_Post\GUI_Post_Untitled\untitled_post_template.py", line 14, in setupUi
    Form_Template.setObjectName("Form_Template")
RuntimeError: super-class __init__() of type post_template was never called

2024-11-02 18:34:59,535 - web_UI - ERROR - Traceback (most recent call last):
  File "C:\Users\16946\Desktop\siwu\Auto_wed_current\Auto_Post\GUI_Post_Template\post_template.py", line 38, in closeEvent
    self.pushButton_data_clear.click()
    ^^^^^^^^^^^^^^^^^^^^^^^^^^
AttributeError: 'post_template' object has no attribute 'pushButton_data_clear'

2024-11-02 18:35:42,805 - web_UI - ERROR - Traceback (most recent call last):
  File "C:\Users\16946\Desktop\siwu\Auto_wed_current\Auto_Post\GUI_Post_Template\post_template.py", line 38, in closeEvent
    self.pushButton_data_clear.click()
    ^^^^^^^^^^^^^^^^^^^^^^^^^^
AttributeError: 'post_template' object has no attribute 'pushButton_data_clear'

